<?xml version="1.0" ?>
<!-- =================================================================================== -->
<!-- |    This document was autogenerated by xacro from jaco_arm.urdf.xacro            | -->
<!-- |    EDITING THIS FILE BY HAND IS NOT RECOMMENDED                                 | -->
<!-- =================================================================================== -->
<robot name="jaco" xmlns:controller="http://playerstage.sourceforge.net/gazebo/xmlschema/#controller" xmlns:interface="http://playerstage.sourceforge.net/gazebo/xmlschema/#interface" xmlns:sensor="http://playerstage.sourceforge.net/gazebo/xmlschema/#sensor" xmlns:xacro="http://ros.org/wiki/xacro">
  <!-- From Kinova Model -->
  <material name="JacoGrey">
    <color rgba="0.2 0.2 0.9 1.0"/>
  </material>
  <link name="jaco_base_link">
    <visual>
      <material name="JacoGrey"/>
      <origin rpy="0 0 1.57079632679" xyz="0 0 0"/>
      <geometry>
        <mesh filename="package://jaco_description/meshes/jaco_base_joint.stl"/>
      </geometry>
    </visual>
    <collision>
      <origin rpy="0 0 1.57079632679" xyz="0 0 0"/>
      <geometry>
        <mesh filename="package://jaco_description/meshes/jaco_base_joint.stl"/>
      </geometry>
    </collision>
  </link>
  <!-- First revolute joint & link -->
  <joint name="jaco_shoulder_yaw_joint" type="revolute">
    <origin rpy="0 0 0" xyz="0 0 0.2102"/>
    <axis rpy="0 0 0" xyz="0 0 1"/>
    <parent link="jaco_base_link"/>
    <child link="jaco_shoulder_link"/>
    <limit effort="1" lower="-3.14159265359" upper="3.14159265359" velocity="3.14159265359"/>
  </joint>
  <link name="jaco_shoulder_link">
    <visual>
      <material name="JacoGrey"/>
      <origin rpy="1.57079632679 -1.57079632679 0" xyz="0 0 0"/>
      <geometry>
        <mesh filename="package://jaco_description/meshes/jaco_shoulder_yaw_joint.stl"/>
      </geometry>
    </visual>
    <collision>
      <origin rpy="1.57079632679 -1.57079632679 0" xyz="0 0 0"/>
      <geometry>
        <mesh filename="package://jaco_description/meshes/jaco_shoulder_yaw_joint.stl"/>
      </geometry>
    </collision>
  </link>
  <!-- Second revolute joint & link -->
  <joint name="jaco_shoulder_pitch_joint" type="revolute">
    <origin rpy="-1.57079632679 0 0" xyz="0 0 0"/>
    <axis xyz="0 0 1"/>
    <parent link="jaco_shoulder_link"/>
    <child link="jaco_upper_arm_link"/>
    <limit effort="1" lower="-3.14159265359" upper="3.14159265359" velocity="3.14159265359"/>
  </joint>
  <link name="jaco_upper_arm_link">
    <visual>
      <material name="JacoGrey"/>
      <origin rpy="0 0 -1.57079632679" xyz="0 0 0"/>
      <geometry>
        <mesh filename="package://jaco_description/meshes/jaco_shoulder_pitch_joint.stl"/>
      </geometry>
    </visual>
    <collision>
      <origin rpy="0 0 -1.57079632679" xyz="0 0 0"/>
      <geometry>
        <mesh filename="package://jaco_description/meshes/jaco_shoulder_pitch_joint.stl"/>
      </geometry>
    </collision>
  </link>
  <!-- Third revolute joint & link -->
  <joint name="jaco_elbow_pitch_joint" type="revolute">
    <origin rpy="0 0 0" xyz="0.41 0 0.012"/>
    <axis xyz="0 0 1"/>
    <parent link="jaco_upper_arm_link"/>
    <child link="jaco_lower_arm_link"/>
    <limit effort="1" lower="-3.14159265359" upper="3.14159265359" velocity="3.14159265359"/>
  </joint>
  <link name="jaco_lower_arm_link">
    <visual>
      <material name="JacoGrey"/>
      <origin rpy="3.14159265359 0 3.14159265359" xyz="0 0 -0.012"/>
      <geometry>
        <mesh filename="package://jaco_description/meshes/jaco_elbow_pitch_joint.stl"/>
      </geometry>
    </visual>
    <collision>
      <origin rpy="3.14159265359 0 3.14159265359" xyz="0 0 -0.012"/>
      <geometry>
        <mesh filename="package://jaco_description/meshes/jaco_elbow_pitch_joint.stl"/>
      </geometry>
    </collision>
  </link>
  <!-- Fourth revolute joint & link -->
  <joint name="jaco_elbow_roll_joint" type="revolute">
    <origin rpy="-1.57079632679 0 0" xyz="0 0.249276823007 0 "/>
    <axis xyz="0 0 1"/>
    <parent link="jaco_lower_arm_link"/>
    <child link="jaco_lower_arm_roll_link"/>
    <limit effort="1" lower="-3.14159265359" upper="3.14159265359" velocity="3.14159265359"/>
  </joint>
  <link name="jaco_lower_arm_roll_link">
    <visual>
      <material name="JacoGrey"/>
      <origin rpy="3.14159265359 0 1.57079632679" xyz="0 0 -0.0422768230075"/>
      <geometry>
        <mesh filename="package://jaco_description/meshes/jaco_elbow_roll_joint.stl"/>
      </geometry>
    </visual>
    <collision>
      <origin rpy="3.14159265359 0 1.57079632679" xyz="0 0 -0.0422768230075"/>
      <geometry>
        <mesh filename="package://jaco_description/meshes/jaco_elbow_roll_joint.stl"/>
      </geometry>
    </collision>
  </link>
  <!-- Fifth revolute joint & link -->
  <joint name="jaco_wrist_roll_joint" type="revolute">
    <origin rpy="0.959931088597 0 0" xyz="0 -0.0692622919853 0.0484979789618"/>
    <axis xyz="0 0 1"/>
    <parent link="jaco_lower_arm_roll_link"/>
    <child link="jaco_wrist_link"/>
    <limit effort="1" lower="-3.14159265359" upper="3.14159265359" velocity="3.14159265359"/>
  </joint>
  <link name="jaco_wrist_link">
    <visual>
      <material name="JacoGrey"/>
      <origin rpy="0 3.14159265359 -1.57079632679" xyz="0 0 -0.0422768230075"/>
      <geometry>
        <mesh filename="package://jaco_description/meshes/jaco_wrist_roll_joint.stl"/>
      </geometry>
    </visual>
    <collision>
      <origin rpy="0 3.14159265359 -1.57079632679" xyz="0 0 -0.0422768230075"/>
      <geometry>
        <mesh filename="package://jaco_description/meshes/jaco_wrist_roll_joint.stl"/>
      </geometry>
    </collision>
  </link>
  <!-- Sixth revolute joint & link -->
  <joint name="jaco_hand_roll_joint" type="revolute">
    <origin rpy="0.959931088597 0 0" xyz="0 -0.186174274186 0.130360630206"/>
    <axis xyz="0 0 1"/>
    <parent link="jaco_wrist_link"/>
    <child link="jaco_hand_link"/>
    <limit effort="1" lower="-3.14159265359" upper="3.14159265359" velocity="3.14159265359"/>
  </joint>
  <link name="jaco_hand_link">
    <visual>
      <material name="JacoGrey"/>
      <origin rpy="0 0 -3.14159265359" xyz="0 0 -0.185"/>
      <geometry>
        <mesh filename="package://jaco_description/meshes/jaco_hand_roll_joint.stl"/>
      </geometry>
    </visual>
    <collision>
      <origin rpy="0 0 -3.14159265359" xyz="0 0 -0.185"/>
      <geometry>
        <mesh filename="package://jaco_description/meshes/jaco_hand_roll_joint.stl"/>
      </geometry>
    </collision>
  </link>
  <!-- First finger (Approximative placing) -->
  <joint name="jaco_finger_1_joint" type="revolute">
    <origin rpy="0 -0.448798950513 0" xyz="-0.036 0.021 -0.07"/>
    <axis xyz="0 1 0"/>
    <parent link="jaco_hand_link"/>
    <child link="jaco_finger_1_link"/>
    <limit effort="1" lower="-3.14159265359" upper="3.14159265359" velocity="3.14159265359"/>
  </joint>
  <link name="jaco_finger_1_link">
    <visual>
      <material name="JacoGrey"/>
      <origin rpy="0 0 0" xyz="0 0 0"/>
      <geometry>
        <mesh filename="package://jaco_description/meshes/finger.dae"/>
      </geometry>
    </visual>
    <collision>
      <origin rpy="0 0 0" xyz="0 0 0"/>
      <geometry>
        <mesh filename="package://jaco_description/meshes/finger.dae"/>
      </geometry>
    </collision>
  </link>
  <!-- Second finger (Approximative placing) -->
  <joint name="jaco_finger_2_joint" type="revolute">
    <origin rpy="0 -0.448798950513 -3.14159265359" xyz="0.036 -0 -0.07"/>
    <axis xyz="0 1 0"/>
    <parent link="jaco_hand_link"/>
    <child link="jaco_finger_2_link"/>
    <limit effort="1" lower="-3.14159265359" upper="3.14159265359" velocity="3.14159265359"/>
  </joint>
  <link name="jaco_finger_2_link">
    <visual>
      <material name="JacoGrey"/>
      <origin rpy="0 0 0" xyz="0 0 0"/>
      <geometry>
        <mesh filename="package://jaco_description/meshes/finger.dae"/>
      </geometry>
    </visual>
    <collision>
      <origin rpy="0 0 0" xyz="0 0 0"/>
      <geometry>
        <mesh filename="package://jaco_description/meshes/finger.dae"/>
      </geometry>
    </collision>
  </link>
  <!-- Third finger (Approximative placing) -->
  <joint name="jaco_finger_3_joint" type="revolute">
    <origin rpy="0 -0.448798950513 0" xyz="-0.036 -0.021 -0.07"/>
    <axis xyz="0 1 0"/>
    <parent link="jaco_hand_link"/>
    <child link="jaco_finger_3_link"/>
    <limit effort="1" lower="-3.14159265359" upper="3.14159265359" velocity="3.14159265359"/>
  </joint>
  <link name="jaco_finger_3_link">
    <visual>
      <material name="JacoGrey"/>
      <origin rpy="0 0 0" xyz="0 0 0"/>
      <geometry>
        <mesh filename="package://jaco_description/meshes/finger.dae"/>
      </geometry>
    </visual>
    <collision>
      <origin rpy="0 0 0" xyz="0 0 0"/>
      <geometry>
        <mesh filename="package://jaco_description/meshes/finger.dae"/>
      </geometry>
    </collision>
  </link>
</robot>

