<?xml version="1.0" ?>
<!-- =================================================================================== -->
<!-- |    This document was autogenerated by xacro from /home/sp/groovy_rosbuild_workspace/kurtana_robot/kurtana_bringup/urdf/kurtana.urdf.xacro | -->
<!-- |    EDITING THIS FILE BY HAND IS NOT RECOMMENDED                                 | -->
<!-- =================================================================================== -->
<robot name="kurtana" xmlns:controller="http://playerstage.sourceforge.net/gazebo/xmlschema/#controller" xmlns:interface="http://playerstage.sourceforge.net/gazebo/xmlschema/#interface" xmlns:sensor="http://playerstage.sourceforge.net/gazebo/xmlschema/#sensor" xmlns:xacro="http://ros.org/wiki/xacro">
  <!-- distance from base_link to top of cover surface -->
  <link name="kurtana_baseplate_link">
    <visual>
      <origin rpy="0 0 0" xyz="0 0 0"/>
      <geometry>
        <box size="0.47 0.368 0.006"/>
      </geometry>
      <material name="grey">
        <color rgba="0.8 0.8 0.8 1"/>
      </material>
    </visual>
    <collision>
      <origin rpy="0 0 0" xyz="0 0 0"/>
      <geometry>
        <box size="0.47 0.368 0.006"/>
      </geometry>
    </collision>
    <inertial>
      <mass value="0.5"/>
      <origin xyz="0 0 0"/>
      <inertia ixx="0.005644164409" ixy="0.0" ixz="0.0" iyy="0.0092056629844" iyz="0.0" izz="0.0148468273946"/>
    </inertial>
  </link>
  <joint name="katana_baseplate_joint" type="fixed">
    <parent link="kurtana_baseplate_link"/>
    <child link="katana_baseplate_link"/>
    <origin xyz="0.05 0 0.009"/>
  </joint>
  <link name="katana_baseplate_link">
    <visual>
      <origin rpy="0 0 0" xyz="0 0 0"/>
      <geometry>
        <box size="0.156 0.156 0.012"/>
      </geometry>
      <material name="grey"/>
    </visual>
    <collision>
      <origin rpy="0 0 0" xyz="0 0 0"/>
      <geometry>
        <box size="0.156 0.156 0.012"/>
      </geometry>
    </collision>
    <inertial>
      <mass value="0.4"/>
      <origin xyz="0 0 0"/>
      <inertia ixx="0.0008159996736" ixy="0.0" ixz="0.0" iyy="0.0008159996736" iyz="0.0" izz="0.00162239935104"/>
    </inertial>
  </link>
  <joint name="kurtana_pole_joint" type="fixed">
    <parent link="kurtana_baseplate_link"/>
    <child link="kurtana_pole_link"/>
    <origin xyz="-0.25 0 0.5"/>
  </joint>
  <link name="kurtana_pole_link">
    <visual>
      <origin rpy="0 0 0" xyz="0 0 0"/>
      <geometry>
        <box size="0.03 0.03 1"/>
      </geometry>
      <material name="grey"/>
    </visual>
    <collision>
      <origin rpy="0 0 0" xyz="0 0 0"/>
      <geometry>
        <box size="0.03 0.03 1"/>
      </geometry>
    </collision>
    <inertial>
      <mass value="3.0"/>
      <origin xyz="0 0 0"/>
      <inertia ixx="0.25022489991" ixy="0.0" ixz="0.0" iyy="0.25022489991" iyz="0.0" izz="0.00044999982"/>
    </inertial>
  </link>
  <joint name="kurtana_microphone_joint" type="fixed">
    <parent link="kurtana_pole_link"/>
    <child link="kurtana_microphone_link"/>
    <origin xyz="0.06 -0.055 0.535"/>
  </joint>
  <link name="kurtana_microphone_link">
    <visual>
      <origin rpy="0 1.57079632679 0" xyz="0 0 0"/>
      <geometry>
        <cylinder length="0.24" radius="0.025"/>
      </geometry>
      <material name="black"/>
    </visual>
    <collision>
      <origin rpy="0 1.57079632679 0" xyz="0 0 0"/>
      <geometry>
        <cylinder length="0.24" radius="0.025"/>
      </geometry>
    </collision>
    <inertial>
      <mass value="0.3"/>
      <origin xyz="0 0 0"/>
      <inertia ixx="0.00148687440525" ixy="0.0" ixz="0.0" iyy="0.00148687440525" iyz="0.0" izz="9.375e-05"/>
    </inertial>
  </link>
  <joint name="kurtana_horizontal_square_bar_joint" type="fixed">
    <parent link="kurtana_pole_link"/>
    <child link="kurtana_horizontal_square_bar_link"/>
    <origin xyz="0.0715 0 0.485"/>
  </joint>
  <link name="kurtana_horizontal_square_bar_link">
    <visual>
      <origin rpy="0 0 0" xyz="0 0 0"/>
      <geometry>
        <box size="0.113 0.03 0.03"/>
      </geometry>
      <material name="grey"/>
    </visual>
    <collision>
      <origin rpy="0 0 0" xyz="0 0 0"/>
      <geometry>
        <box size="0.113 0.03 0.03"/>
      </geometry>
    </collision>
    <inertial>
      <mass value="0.1"/>
      <origin xyz="0 0 0"/>
      <inertia ixx="1.4999994e-05" ixy="0.0" ixz="0.0" iyy="0.00011390828777" iyz="0.0" izz="0.00011390828777"/>
    </inertial>
  </link>
  <joint name="kurtana_vertical_square_bar_joint" type="fixed">
    <parent link="kurtana_horizontal_square_bar_link"/>
    <child link="kurtana_vertical_square_bar_link"/>
    <origin xyz="0.0415 0 0.05875"/>
  </joint>
  <link name="kurtana_vertical_square_bar_link">
    <visual>
      <origin rpy="0 0 0" xyz="0 0 0"/>
      <geometry>
        <box size="0.03 0.03 0.0875"/>
      </geometry>
      <material name="grey"/>
    </visual>
    <collision>
      <origin rpy="0 0 0" xyz="0 0 0"/>
      <geometry>
        <box size="0.03 0.03 0.0875"/>
      </geometry>
    </collision>
    <inertial>
      <mass value="0.1"/>
      <origin xyz="0 0 0"/>
      <inertia ixx="7.13020548125e-05" ixy="0.0" ixz="0.0" iyy="7.13020548125e-05" iyz="0.0" izz="1.4999994e-05"/>
    </inertial>
  </link>
  <joint name="kurtana_roll_servo_joint" type="fixed">
    <parent link="kurtana_vertical_square_bar_link"/>
    <child link="kurtana_roll_servo_link"/>
    <origin xyz="0.049 0 0.01875"/>
  </joint>
  <link name="kurtana_roll_servo_link">
    <visual>
      <origin rpy="0 0 0" xyz="0 0 0"/>
      <geometry>
        <box size="0.068 0.032 0.05"/>
      </geometry>
      <material name="grey"/>
    </visual>
    <collision>
      <origin rpy="0 0 0" xyz="0 0 0"/>
      <geometry>
        <box size="0.068 0.032 0.05"/>
      </geometry>
    </collision>
    <inertial>
      <mass value="0.15"/>
      <origin xyz="0 0 0"/>
      <inertia ixx="4.404998238e-05" ixy="0.0" ixz="0.0" iyy="8.904996438e-05" iyz="0.0" izz="7.059997176e-05"/>
    </inertial>
  </link>
  <joint name="kurtana_roll_joint" type="revolute">
    <parent link="kurtana_roll_servo_link"/>
    <child link="kurtana_pitch_servo_link"/>
    <origin xyz="0.008 0 0.059"/>
    <axis xyz="0 0 1"/>
    <limit effort="1000.0" lower="-0.5" upper="0.5" velocity="2.0"/>
  </joint>
  <link name="kurtana_pitch_servo_link">
    <visual>
      <origin rpy="0 0 0" xyz="0 0 0"/>
      <geometry>
        <box size="0.032 0.05 0.068"/>
      </geometry>
      <material name="grey"/>
    </visual>
    <collision>
      <origin rpy="0 0 0" xyz="0 0 0"/>
      <geometry>
        <box size="0.032 0.05 0.068"/>
      </geometry>
    </collision>
    <inertial>
      <mass value="0.15"/>
      <origin xyz="0 0 0"/>
      <inertia ixx="8.904996438e-05" ixy="0.0" ixz="0.0" iyy="7.059997176e-05" iyz="0.0" izz="4.404998238e-05"/>
    </inertial>
  </link>
  <joint name="kurtana_pitch_joint" type="revolute">
    <parent link="kurtana_pitch_servo_link"/>
    <child link="kurtana_pitch_servo_movable_part_link"/>
    <origin rpy="0 0.045 0" xyz="0 0 0.008"/>
    <axis xyz="0 1 0"/>
    <limit effort="1000.0" lower="0.8" upper="1.2" velocity="2.0"/>
  </joint>
  <link name="kurtana_pitch_servo_movable_part_link">
    <visual>
      <origin rpy="0 0 0" xyz="0 0 0"/>
      <geometry>
        <box size="0.032 0.05 0.035"/>
      </geometry>
      <material name="grey"/>
    </visual>
    <collision>
      <origin rpy="0 0 0" xyz="0 0 0"/>
      <geometry>
        <box size="0.032 0.05 0.035"/>
      </geometry>
    </collision>
    <inertial>
      <mass value="0.15"/>
      <origin xyz="0 0 0"/>
      <inertia ixx="4.6562481375e-05" ixy="0.0" ixz="0.0" iyy="2.8112488755e-05" iyz="0.0" izz="4.404998238e-05"/>
    </inertial>
  </link>
  <joint name="kurtana_kinect_mounting_plate_joint" type="fixed">
    <parent link="kurtana_pitch_servo_movable_part_link"/>
    <child link="kurtana_kinect_mounting_plate_link"/>
    <origin rpy="0 0 0" xyz="0 0 0.021"/>
  </joint>
  <link name="kurtana_kinect_mounting_plate_link">
    <visual>
      <origin rpy="0 0 0" xyz="0 0 0"/>
      <geometry>
        <box size="0.045 0.17 0.007"/>
      </geometry>
      <material name="grey"/>
    </visual>
    <collision>
      <origin rpy="0 0 0" xyz="0 0 0"/>
      <geometry>
        <box size="0.045 0.17 0.007"/>
      </geometry>
    </collision>
    <inertial>
      <mass value="0.05"/>
      <origin xyz="0 0 0"/>
      <inertia ixx="0.000120620785085" ixy="0.0" ixz="0.0" iyy="8.64166321e-06" iyz="0.0" izz="0.000128854115125"/>
    </inertial>
  </link>
  <gazebo reference="kurtana_rackplate_link">
    <material value="PR2/Grey"/>
  </gazebo>
  <gazebo reference="kurtana_baseplate_link">
    <material value="PR2/Grey"/>
  </gazebo>
  <gazebo reference="kurtana_pole_link">
    <material value="PR2/Grey"/>
  </gazebo>
  <gazebo reference="kurtana_innerpole_stretch_link">
    <material value="PR2/Grey"/>
  </gazebo>
  <gazebo reference="kurtana_poletop_roll_link">
    <material value="PR2/Grey"/>
  </gazebo>
  <gazebo reference="kurtana_pitchpole_link">
    <material value="PR2/Grey"/>
  </gazebo>
  <link name="kinect_link">
    <visual>
      <origin rpy="0 0 0" xyz="0 0 0"/>
      <geometry>
        <mesh filename="package://pr2_description/meshes/sensors/kinect_v0/kinect.dae" scale="0.001 0.001 0.001"/>
      </geometry>
    </visual>
    <collision>
      <origin rpy="0 0 0" xyz="-0.0315 0 -0.017"/>
      <geometry>
        <box size="0.0730 0.2760 0.0720"/>
      </geometry>
    </collision>
    <inertial>
      <mass value="0.43"/>
      <origin xyz="0 0 0"/>
      <inertia ixx="0.00291539883384" ixy="0.0" ixz="0.0" iyy="0.000376715682647" iyz="0.0" izz="0.0029205946651"/>
    </inertial>
  </link>
  <joint name="kinect_depth_joint" type="fixed">
    <origin rpy="0 0 0" xyz="0 0.018 0"/>
    <parent link="kinect_link"/>
    <child link="kinect_depth_frame"/>
  </joint>
  <link name="kinect_depth_frame">
    <inertial>
      <mass value="0.000001"/>
      <origin xyz="0 0 0"/>
      <inertia ixx="0.0001" ixy="0.0" ixz="0.0" iyy="0.0001" iyz="0.0" izz="0.0001"/>
    </inertial>
  </link>
  <joint name="kinect_depth_optical_joint" type="fixed">
    <origin rpy="-1.57079632679 0 -1.57079632679" xyz="0 0 0"/>
    <parent link="kinect_depth_frame"/>
    <child link="kinect_depth_optical_frame"/>
  </joint>
  <link name="kinect_depth_optical_frame">
    <inertial>
      <mass value="0.000001"/>
      <origin xyz="0 0 0"/>
      <inertia ixx="0.0001" ixy="0.0" ixz="0.0" iyy="0.0001" iyz="0.0" izz="0.0001"/>
    </inertial>
  </link>
  <joint name="kinect_rgb_joint" type="fixed">
    <origin rpy="0 0 0" xyz="0 -0.005 0"/>
    <parent link="kinect_link"/>
    <child link="kinect_rgb_frame"/>
  </joint>
  <link name="kinect_rgb_frame">
    <inertial>
      <mass value="0.000001"/>
      <origin xyz="0 0 0"/>
      <inertia ixx="0.0001" ixy="0.0" ixz="0.0" iyy="0.0001" iyz="0.0" izz="0.0001"/>
    </inertial>
  </link>
  <joint name="kinect_rgb_optical_joint" type="fixed">
    <origin rpy="-1.57079632679 0 -1.57079632679" xyz="0 0 0"/>
    <parent link="kinect_rgb_frame"/>
    <child link="kinect_rgb_optical_frame"/>
  </joint>
  <link name="kinect_rgb_optical_frame">
    <inertial>
      <mass value="0.000001"/>
      <origin xyz="0 0 0"/>
      <inertia ixx="0.0001" ixy="0.0" ixz="0.0" iyy="0.0001" iyz="0.0" izz="0.0001"/>
    </inertial>
  </link>
  <joint name="kurtana_kinect_joint" type="fixed">
    <parent link="kurtana_kinect_mounting_plate_link"/>
    <child link="kinect_link"/>
    <origin rpy="0 0 0" xyz="0.03 0.0 0.02"/>
  </joint>
  <gazebo>
    <plugin filename="libgazebo_ros_controller_manager.so" name="gazebo_ros_controller_manager">
      <alwaysOn>true</alwaysOn>
      <updateRate>1000.0</updateRate>
      <robotParam>robot_description</robotParam>
    </plugin>
  </gazebo>
  <transmission name="jaco_1_trans" type="pr2_mechanism_model/SimpleTransmission">
    <actuator name="jaco_1_motor"/>
    <joint name="jaco_joint_1"/>
    <mechanicalReduction>1</mechanicalReduction>
    <motorTorqueConstant>1</motorTorqueConstant>
  </transmission>
  <transmission name="jaco_2_trans" type="pr2_mechanism_model/SimpleTransmission">
    <actuator name="jaco_2_motor"/>
    <joint name="jaco_joint_2"/>
    <mechanicalReduction>1</mechanicalReduction>
    <motorTorqueConstant>1</motorTorqueConstant>
  </transmission>
  <transmission name="jaco_3_trans" type="pr2_mechanism_model/SimpleTransmission">
    <actuator name="jaco_3_motor"/>
    <joint name="jaco_joint_3"/>
    <mechanicalReduction>1</mechanicalReduction>
    <motorTorqueConstant>1</motorTorqueConstant>
  </transmission>
  <transmission name="jaco_4_trans" type="pr2_mechanism_model/SimpleTransmission">
    <actuator name="jaco_4_motor"/>
    <joint name="jaco_joint_4"/>
    <mechanicalReduction>1</mechanicalReduction>
    <motorTorqueConstant>1</motorTorqueConstant>
  </transmission>
  <transmission name="jaco_5_trans" type="pr2_mechanism_model/SimpleTransmission">
    <actuator name="jaco_5_motor"/>
    <joint name="jaco_joint_5"/>
    <mechanicalReduction>1</mechanicalReduction>
    <motorTorqueConstant>1</motorTorqueConstant>
  </transmission>
  <transmission name="jaco_6_trans" type="pr2_mechanism_model/SimpleTransmission">
    <actuator name="jaco_6_motor"/>
    <joint name="jaco_joint_6"/>
    <mechanicalReduction>1</mechanicalReduction>
    <motorTorqueConstant>1</motorTorqueConstant>
  </transmission>
  <transmission name="jaco_finger_1_trans" type="pr2_mechanism_model/SimpleTransmission">
    <actuator name="jaco_finger_1_motor"/>
    <joint name="jaco_finger_joint_1"/>
    <mechanicalReduction>1</mechanicalReduction>
    <motorTorqueConstant>1</motorTorqueConstant>
  </transmission>
  <transmission name="jaco_finger_2_trans" type="pr2_mechanism_model/SimpleTransmission">
    <actuator name="jaco_finger_2_motor"/>
    <joint name="jaco_finger_joint_2"/>
    <mechanicalReduction>1</mechanicalReduction>
    <motorTorqueConstant>1</motorTorqueConstant>
  </transmission>
  <transmission name="jaco_finger_3_trans" type="pr2_mechanism_model/SimpleTransmission">
    <actuator name="jaco_finger_3_motor"/>
    <joint name="jaco_finger_joint_3"/>
    <mechanicalReduction>1</mechanicalReduction>
    <motorTorqueConstant>1</motorTorqueConstant>
  </transmission>
  <material name="JacoGrey">
    <color rgba="0.2 0.2 0.9 1.0"/>
  </material>
  <link name="jaco_base_link">
    <inertial>
      <mass value="1"/>
      <!--origin xyz="0 0 -0.0525" rpy="0 0 0"/-->
      <origin rpy="0 0 0" xyz="0 0 0.0"/>
      <inertia ixx="1" ixy="0" ixz="0" iyy="1" iyz="0" izz="1"/>
    </inertial>
    <visual>
      <material name="JacoGrey"/>
      <!--origin xyz="0 0 -0.0525" rpy="0 0 0"/-->
      <geometry>
        <mesh filename="package://jaco_description/meshes/joint_1.stl" scale="0.001 0.001 0.001"/>
      </geometry>
    </visual>
    <collision>
      <!--origin xyz="0 0 -0.0525" rpy="0 0 0"/-->
      <geometry>
        <mesh filename="package://jaco_description/meshes/joint_1.stl" scale="0.001 0.001 0.001"/>
      </geometry>
    </collision>
  </link>
  <gazebo reference="jaco_base_link">
    <material>Gazebo/Yellow</material>
    <turnGravityOff>true</turnGravityOff>
  </gazebo>
  <joint name="jaco_joint_1" type="revolute">
    <!--origin xyz="0 0 0.2102" rpy="0 0 0"/-->
    <origin rpy="0 0 0" xyz="0 0 0.2725"/>
    <axis rpy="0 0 0" xyz="0 0 -1"/>
    <parent link="jaco_base_link"/>
    <child link="jaco_link_1"/>
    <limit effort="30" lower="-3.1415926535897931" upper="3.1415926535897931" velocity="5"/>
  </joint>
  <link name="jaco_link_1">
    <inertial>
      <mass value="1"/>
      <inertia ixx="1" ixy="0" ixz="0" iyy="1" iyz="0" izz="1"/>
      <origin/>
    </inertial>
    <visual>
      <material name="JacoGrey"/>
      <origin rpy="0 0 -1.570796327" xyz="0 0 -0.12"/>
      <geometry>
        <mesh filename="package://jaco_description/meshes/joint_2.stl" scale="0.001 0.001 0.001"/>
      </geometry>
    </visual>
    <collision>
      <origin rpy="0 0 -1.570796327" xyz="0 0 -0.12"/>
      <geometry>
        <mesh filename="package://jaco_description/meshes/joint_2.stl" scale="0.001 0.001 0.001"/>
      </geometry>
    </collision>
  </link>
  <gazebo reference="jaco_link_1">
    <material>Gazebo/Red</material>
    <turnGravityOff>true</turnGravityOff>
  </gazebo>
  <joint name="jaco_joint_2" type="revolute">
    <origin rpy="-1.570796327 0 0" xyz="0 0 0"/>
    <axis xyz="0 0 1"/>
    <parent link="jaco_link_1"/>
    <child link="jaco_link_2"/>
    <limit effort="30" lower="-3.6651914291881" upper="0.57595865315813" velocity="5"/>
  </joint>
  <link name="jaco_link_2">
    <inertial>
      <mass value="1"/>
      <inertia ixx="1" ixy="0" ixz="0" iyy="1" iyz="0" izz="1"/>
      <origin/>
    </inertial>
    <visual>
      <material name="JacoGrey"/>
      <origin rpy="0 1.570796327 0" xyz="0 0 0.015"/>
      <geometry>
        <mesh filename="package://jaco_description/meshes/joint_3.stl" scale="0.001 0.001 0.001"/>
      </geometry>
    </visual>
    <collision>
      <origin rpy="0 1.570796327 0" xyz="0 0 0.015"/>
      <geometry>
        <mesh filename="package://jaco_description/meshes/joint_3.stl" scale="0.001 0.001 0.001"/>
      </geometry>
    </collision>
  </link>
  <gazebo reference="jaco_link_2">
    <material>Gazebo/Blue</material>
    <turnGravityOff>true</turnGravityOff>
  </gazebo>
  <joint name="jaco_joint_3" type="revolute">
    <origin rpy="0 0 0" xyz="0.4100 0 0.012"/>
    <axis xyz="0 0 -1"/>
    <parent link="jaco_link_2"/>
    <child link="jaco_link_3"/>
    <limit effort="30" lower="-1.221730476396" upper="4.2935099599061" velocity="5"/>
  </joint>
  <link name="jaco_link_3">
    <inertial>
      <mass value="1"/>
      <inertia ixx="1" ixy="0" ixz="0" iyy="1" iyz="0" izz="1"/>
      <origin/>
    </inertial>
    <visual>
      <material name="JacoGrey"/>
      <origin rpy="0 1.570796327 1.570796327" xyz="0 0 -0.012"/>
      <geometry>
        <mesh filename="package://jaco_description/meshes/joint_4.stl" scale="1.000 1.000 1.000"/>
      </geometry>
    </visual>
    <collision>
      <origin rpy="0 1.570796327 1.570796327" xyz="0 0 -0.012"/>
      <geometry>
        <mesh filename="package://jaco_description/meshes/joint_4.stl" scale="1.000 1.000 1.000"/>
      </geometry>
    </collision>
  </link>
  <gazebo reference="jaco_link_3">
    <material>Gazebo/Red</material>
    <turnGravityOff>true</turnGravityOff>
  </gazebo>
  <joint name="jaco_joint_4" type="revolute">
    <origin rpy="-1.570796327 0 0" xyz="0 0.24927682300748782 0 "/>
    <axis xyz="0 0 -1"/>
    <parent link="jaco_link_3"/>
    <child link="jaco_link_4"/>
    <limit effort="30" lower="-3.1415926535897931" upper="3.1415926535897931" velocity="5"/>
  </joint>
  <link name="jaco_link_4">
    <inertial>
      <mass value="1"/>
      <inertia ixx="1" ixy="0" ixz="0" iyy="1" iyz="0" izz="1"/>
      <origin/>
    </inertial>
    <visual>
      <material name="JacoGrey"/>
      <origin rpy="0 0 -1.570796327" xyz="0 0 -0.042276823"/>
      <geometry>
        <mesh filename="package://jaco_description/meshes/joint_5.stl" scale="0.001 0.001 0.001"/>
      </geometry>
    </visual>
    <collision>
      <origin rpy="0 0 -1.570796327" xyz="0 0 -0.042276823"/>
      <geometry>
        <mesh filename="package://jaco_description/meshes/joint_5.stl" scale="0.001 0.001 0.001"/>
      </geometry>
    </collision>
  </link>
  <gazebo reference="jaco_link_4">
    <material>Gazebo/Blue</material>
    <turnGravityOff>true</turnGravityOff>
  </gazebo>
  <joint name="jaco_joint_5" type="revolute">
    <origin rpy="0.959931089 0 0" xyz="0 -0.069262292 0.048497979"/>
    <axis xyz="0 0 -1"/>
    <parent link="jaco_link_4"/>
    <child link="jaco_link_5"/>
    <limit effort="30" lower="-3.1415926535897931" upper="3.1415926535897931" velocity="5"/>
  </joint>
  <link name="jaco_link_5">
    <inertial>
      <mass value="1.0"/>
      <inertia ixx="1" ixy="0" ixz="0" iyy="1" iyz="0" izz="1"/>
      <origin/>
    </inertial>
    <visual>
      <material name="JacoGrey"/>
      <origin rpy="0 -0.959931089 1.570796327" xyz="0 0 -0.042276823"/>
      <geometry>
        <mesh filename="package://jaco_description/meshes/joint_6.stl" scale="0.001 0.001 0.001"/>
      </geometry>
    </visual>
    <collision>
      <origin rpy="0 -0.959931089 1.570796327" xyz="0 0 -0.042276823"/>
      <geometry>
        <mesh filename="package://jaco_description/meshes/joint_6.stl" scale="0.001 0.001 0.001"/>
      </geometry>
    </collision>
  </link>
  <gazebo reference="jaco_link_5">
    <material>Gazebo/Red</material>
    <turnGravityOff>true</turnGravityOff>
  </gazebo>
  <joint name="jaco_joint_6" type="revolute">
    <!--origin xyz="0 -0.186174274 0.13036063" rpy="0.959931089 0 0"/-->
    <origin rpy="-0.959931089 0 3.1415926535897931" xyz="0 -0.186174274 0.13036063"/>
    <origin rpy="0 0 -3.14" xyz="0 0 0"/>
    <axis xyz="0 0 -1"/>
    <parent link="jaco_link_5"/>
    <child link="jaco_link_6"/>
    <limit effort="30" lower="-3.5415926535897931" upper="3.5415926535897931" velocity="5"/>
  </joint>
  <link name="jaco_link_6">
    <inertial>
      <mass value="0.3"/>
      <inertia ixx="1" ixy="0" ixz="0" iyy="1" iyz="0" izz="1"/>
      <origin/>
    </inertial>
    <visual>
      <material name="JacoGrey"/>
      <!--origin xyz="0 0 -0.1850" rpy="0 0 -3.1415926535897931"/-->
      <origin rpy="0 0 0" xyz="0 0 -0.1850"/>
      <geometry>
        <mesh filename="package://jaco_description/meshes/hand_with_noFinger.stl" scale="0.001 0.001 0.001"/>
      </geometry>
    </visual>
    <collision>
      <!--origin xyz="0 0 -0.1850" rpy="0 0 -3.1415926535897931"/-->
      <origin rpy="0 0 0" xyz="0 0 -0.1850"/>
      <geometry>
        <mesh filename="package://jaco_description/meshes/hand_with_noFinger.stl" scale="0.001 0.001 0.001"/>
      </geometry>
    </collision>
  </link>
  <gazebo reference="jaco_link_6">
    <material>Gazebo/Blue</material>
    <turnGravityOff>true</turnGravityOff>
  </gazebo>
  <joint name="jaco_gripper_tool_frame_joint" type="fixed">
    <parent link="jaco_link_6"/>
    <child link="jaco_gripper_tool_frame"/>
    <origin rpy="-0.2 -1.57079632679 1.57079632679" xyz="0 0 -0.08"/>
  </joint>
  <link name="jaco_gripper_tool_frame">
    <!-- This is the coordinate system of the tool (this is the position
         used in IK etc., relative to the base frame); there is no actual
         arm part attached to this link -->
  </link>
  <joint name="jaco_finger_joint_1" type="revolute">
    <!--origin xyz="-0.036 -0.021 -0.07" rpy="0 0 0"/-->
    <!-- changed becuase it look funny in simulation-->
    <origin rpy="0 0 0" xyz="-0.036 -0.021 -0.09"/>
    <axis xyz="0 1 0"/>
    <parent link="jaco_link_6"/>
    <child link="jaco_finger_link_1"/>
    <limit effort="30" lower="-3.1415926535897931" upper="3.1415926535897931" velocity="5"/>
  </joint>
  <link name="jaco_finger_link_1">
    <inertial>
      <mass value="0.05"/>
      <inertia ixx="1" ixy="0" ixz="0" iyy="1" iyz="0" izz="1"/>
      <origin/>
    </inertial>
    <visual>
      <origin rpy="0 0 0" xyz="0 0 0"/>
      <geometry>
        <mesh filename="package://jaco_description/meshes/finger.stl" scale="1 1 1"/>
      </geometry>
    </visual>
    <collision>
      <origin rpy="0 0 0" xyz="0 0 0"/>
      <geometry>
        <mesh filename="package://jaco_description/meshes/finger.stl" scale="1 1 1"/>
      </geometry>
    </collision>
  </link>
  <gazebo reference="jaco_finger_link_1">
    <material>Gazebo/Blue</material>
    <turnGravityOff>true</turnGravityOff>
  </gazebo>
  <joint name="jaco_finger_joint_2" type="revolute">
    <!--origin xyz="-0.036 0.021 -0.07" rpy="0 0 0"/-->
    <origin rpy="0 0 0" xyz="-0.036 0.021 -0.09"/>
    <axis xyz="0 1 0"/>
    <parent link="jaco_link_6"/>
    <child link="jaco_finger_link_2"/>
    <limit effort="30" lower="-3.1415926535897931" upper="3.1415926535897931" velocity="5"/>
  </joint>
  <link name="jaco_finger_link_2">
    <inertial>
      <mass value="0.05"/>
      <inertia ixx="1" ixy="0" ixz="0" iyy="1" iyz="0" izz="1"/>
      <origin/>
    </inertial>
    <visual>
      <origin rpy="0 0 0" xyz="0 0 0"/>
      <geometry>
        <mesh filename="package://jaco_description/meshes/finger.stl" scale="1 1 1"/>
      </geometry>
    </visual>
    <collision>
      <origin rpy="0 0 0" xyz="0 0 0"/>
      <geometry>
        <mesh filename="package://jaco_description/meshes/finger.stl" scale="1 1 1"/>
      </geometry>
    </collision>
  </link>
  <gazebo reference="jaco_finger_link_2">
    <material>Gazebo/Blue</material>
    <turnGravityOff>true</turnGravityOff>
  </gazebo>
  <joint name="jaco_finger_joint_3" type="revolute">
    <!--origin xyz="0.036 -0 -0.07" rpy="0 0 3.14"/-->
    <origin rpy="0 0 3.14" xyz="0.036 -0 -0.09"/>
    <axis xyz="0 1 0"/>
    <parent link="jaco_link_6"/>
    <child link="jaco_finger_link_3"/>
    <limit effort="30" lower="-3.1415926535897931" upper="3.1415926535897931" velocity="5"/>
  </joint>
  <link name="jaco_finger_link_3">
    <inertial>
      <mass value="0.05"/>
      <inertia ixx="1" ixy="0" ixz="0" iyy="1" iyz="0" izz="1"/>
      <origin/>
    </inertial>
    <visual>
      <origin rpy="0 0 0" xyz="0 0 0"/>
      <geometry>
        <mesh filename="package://jaco_description/meshes/finger.stl" scale="1 1 1"/>
      </geometry>
    </visual>
    <collision>
      <origin rpy="0 0 0" xyz="0 0 0"/>
      <geometry>
        <mesh filename="package://jaco_description/meshes/finger.stl" scale="1 1 1"/>
      </geometry>
    </collision>
  </link>
  <gazebo reference="jaco_finger_link_3">
    <material>Gazebo/Blue</material>
    <turnGravityOff>true</turnGravityOff>
  </gazebo>
  <joint name="kurtana_baseplate_katana_baseplate_joint" type="fixed">
    <parent link="katana_baseplate_link"/>
    <child link="jaco_base_link"/>
    <origin rpy="1.57079632679 3.14159265359 1.57079632679" xyz="-0.27 0 0.27"/>
  </joint>
  <link name="base_link">
    <visual name="base_visual">
      <origin rpy="0 0 0" xyz="-0.045 0 0.148"/>
      <geometry name="pioneer_geom">
        <mesh filename="package://p2os_urdf/meshes/p3dx_meshes/chassis.stl"/>
      </geometry>
      <material name="ChassisRed">
        <color rgba="0.851 0.0 0.0 1.0"/>
      </material>
    </visual>
    <inertial>
      <mass value="500"/>
      <inertia ixx="500" ixy="0" ixz="0" iyy="500" iyz="0" izz="500"/>
      <origin/>
    </inertial>
    <collision>
      <origin rpy="0 0 0" xyz="-0.045 0 0.148"/>
      <geometry name="pioneer_geom">
        <mesh filename="package://p2os_urdf/meshes/p3dx_meshes/chassis.stl"/>
      </geometry>
    </collision>
  </link>
  <gazebo reference="base_link">
    <material value="Gazebo/Red"/>
  </gazebo>
  <joint name="base_joint" type="fixed">
    <parent link="base_link"/>
    <child link="kurtana_baseplate_link"/>
    <origin xyz="0 0.0 0.6115"/>
  </joint>
</robot>

