<?xml version="1.0" ?>
<!-- =================================================================================== -->
<!-- |    This document was autogenerated by xacro from asrob.urdf.xacro               | -->
<!-- |    EDITING THIS FILE BY HAND IS NOT RECOMMENDED                                 | -->
<!-- =================================================================================== -->
<robot name="asrob" xmlns:controller="http://playerstage.sourceforge.net/gazebo/xmlschema/#controller" xmlns:interface="http://playerstage.sourceforge.net/gazebo/xmlschema/#interface" xmlns:sensor="http://playerstage.sourceforge.net/gazebo/xmlschema/#sensor" xmlns:xacro="http://ros.org/wiki/xacro">
  <!-- base-->
  <material name="IPA/LightGrey">
    <color rgba="0.7 0.7 0.7 1.0"/>
  </material>
  <material name="IPA/DarkGrey">
    <color rgba="0.4 0.4 0.4 1.0"/>
  </material>
  <material name="IPA/Orange">
    <color rgba="1.0 0.4 0.0 1.0"/>
  </material>
  <material name="IPA/Black">
    <color rgba="0.0 0.0 0.0 1.0"/>
  </material>
  <material name="IPA/Blue">
    <color rgba="0.0 0.0 0.5 1.0"/>
  </material>
  <gazebo>
    <plugin filename="libgazebo_ros_controller_manager.so" name="gazebo_ros_controller_manager">
      <alwaysOn>true</alwaysOn>
      <updateRate>1000.0</updateRate>
    </plugin>
    <plugin filename="libgazebo_ros_power_monitor.so" name="gazebo_ros_power_monitor_controller">
      <alwaysOn>true</alwaysOn>
      <updateRate>1.0</updateRate>
      <timeout>5</timeout>
      <powerStateTopic>power_state</powerStateTopic>
      <powerStateRate>10.0</powerStateRate>
      <fullChargeCapacity>87.78</fullChargeCapacity>
      <dischargeRate>-474</dischargeRate>
      <chargeRate>525</chargeRate>
      <dischargeVoltage>15.52</dischargeVoltage>
      <chargeVoltage>16.41</chargeVoltage>
    </plugin>
  </gazebo>
  <link name="base_link">
    <inertial>
      <mass value="116.0"/>
      <origin xyz="0 0 0"/>
      <inertia ixx="5.652232699207" ixy="-0.009719934438" ixz="1.293988226423" iyy="5.669473158652" iyz="-0.007379583694" izz="3.683196351726"/>
    </inertial>
    <visual>
      <origin rpy="0 0 0" xyz="0 0 0.27"/>
      <geometry>
        <!--mesh filename="package://cob_description/meshes/base/base.stl"/-->
        <box size="0.62 0.48 0.17"/>
      </geometry>
      <material name="Grey"/>
    </visual>
    <collision>
      <origin rpy="0 0 0" xyz="0 0 0.27"/>
      <geometry>
        <!--box size="0.001 0.001 0.001" /-->
        <!--mesh filename="package://cob_description/meshes/base/base_collision.stlb"/!-->
        <box size="0.62 0.48 0.17"/>
      </geometry>
    </collision>
  </link>
  <link name="base_footprint">
    <inertial>
      <mass value="1.0"/>
      <origin xyz="0 0 0"/>
      <inertia ixx="0.01" ixy="0.0" ixz="0.0" iyy="0.01" iyz="0.0" izz="0.01"/>
    </inertial>
    <visual>
      <origin rpy="0 0 0" xyz="0 0 0"/>
      <geometry>
        <box size="0.01 0.01 0.01"/>
      </geometry>
      <material name="Red"/>
    </visual>
    <collision>
      <origin rpy="0 0 0" xyz="0 0 0.1"/>
      <geometry>
        <box size="0.001 0.001 0.001"/>
      </geometry>
    </collision>
  </link>
  <joint name="base_footprint_joint" type="fixed">
    <origin rpy="0 0 0" xyz="0 0 0"/>
    <child link="base_link"/>
    <parent link="base_footprint"/>
  </joint>
  <joint name="base_laser_front_joint" type="fixed">
    <axis xyz="0 1 0"/>
    <origin rpy="0 0 0" xyz="0.325 0.0 0.135"/>
    <parent link="base_link"/>
    <child link="base_laser_front_link"/>
  </joint>
  <link name="base_laser_front_link" type="laser">
    <inertial>
      <mass value="0.001"/>
      <origin rpy="0 0 0" xyz="0 0 0"/>
      <inertia ixx="0.0001" ixy="0" ixz="0" iyy="0.000001" iyz="0" izz="0.0001"/>
    </inertial>
    <visual>
      <origin rpy="0 0 0" xyz="0 0 0"/>
      <geometry>
        <mesh filename="package://cob_description/meshes/sensors/sick_s300_laser.dae"/>
        <!--box size="0.001 0.001 0.001" /-->
      </geometry>
      <material name="IPA/LightGrey"/>
    </visual>
    <collision>
      <origin rpy="0 0 0" xyz="0 0 0"/>
      <geometry>
        <cylinder length="0.09" radius="0.044"/>
      </geometry>
    </collision>
  </link>
  <gazebo reference="base_laser_front_link">
    <sensor name="base_laser_front" type="ray">
      <always_on>true</always_on>
      <update_rate>10</update_rate>
      <pose>0 0 0 0 0 0</pose>
      <visualize>false</visualize>
      <ray>
        <scan>
          <horizontal>
            <samples>541</samples>
            <resolution>1.0</resolution>
            <min_angle>-2.3562</min_angle>
            <max_angle>2.3562</max_angle>
          </horizontal>
        </scan>
        <range>
          <min>0.05</min>
          <max>30.0</max>
          <resolution>0.03</resolution>
        </range>
      </ray>
      <plugin filename="libgazebo_ros_laser.so" name="gazebo_ros_base_laser_front_controller">
        <gaussianNoise>0.005</gaussianNoise>
        <alwaysOn>true</alwaysOn>
        <updateRate>10</updateRate>
        <topicName>/sick_s300/scan_unfiltered</topicName>
        <frameName>base_laser_front_link</frameName>
      </plugin>
    </sensor>
    <!--material value="IPA/LightGrey" /-->
  </gazebo>
  <joint name="fl_caster_rotation_joint" type="continuous">
    <axis xyz="0 0 1"/>
    <limit effort="100" velocity="100"/>
    <!-- alpha tested velocity and effort limits -->
    <safety_controller k_velocity="10"/>
    <calibration rising="-0.785398163397"/>
    <dynamics damping="0.0" friction="0.0"/>
    <origin rpy="0 0 0" xyz="0.235 0.185 0.075"/>
    <parent link="base_link"/>
    <child link="fl_caster_rotation_link"/>
  </joint>
  <link name="fl_caster_rotation_link">
    <inertial>
      <mass value="3.473082"/>
      <origin xyz="0 0 0.07"/>
      <inertia ixx="0.012411765597" ixy="-0.000711733678" ixz="0.00050272983" iyy="0.015218160428" iyz="-0.000004273467" izz="0.011763977943"/>
    </inertial>
    <visual>
      <!--origin xyz="0 0 0.085" rpy="0 0 0" /-->
      <!--modified by jie-->
      <origin rpy="0.0 0.0 0.0" xyz="0 0 0.002"/>
      <geometry>
        <!--mesh filename="package://cob_description/meshes/base/caster.stl" /-->
        <!--modified by jie-->
        <!--box size="0.192 0.164 0.013" /-->
        <box size="0.001 0.001 0.001"/>
      </geometry>
      <material name="Green"/>
    </visual>
    <collision>
      <origin rpy="0.0 0.0 0.0" xyz="0 0 0.002"/>
      <geometry>
        <box size="0.001 0.001 0.001"/>
      </geometry>
    </collision>
  </link>
  <transmission name="fl_caster_rotation_trans" type="pr2_mechanism_model/SimpleTransmission">
    <actuator name="fl_caster_rotation_motor"/>
    <joint name="fl_caster_rotation_joint"/>
    <mechanicalReduction>-79.2380952381</mechanicalReduction>
  </transmission>
  <joint name="fl_caster_r_wheel_joint" type="continuous">
    <axis xyz="0 1 0"/>
    <limit effort="100" velocity="100"/>
    <!-- alpha tested effort and velocity limits -->
    <safety_controller k_velocity="10"/>
    <dynamics damping="0.0" friction="0.0"/>
    <origin rpy="0 0 0" xyz="0 -0.0 0"/>
    <parent link="fl_caster_rotation_link"/>
    <child link="fl_caster_r_wheel_link"/>
  </joint>
  <link name="fl_caster_r_wheel_link">
    <inertial>
      <mass value="0.44036"/>
      <origin xyz="0 0 0"/>
      <inertia ixx="0.012411765597" ixy="-0.000711733678" ixz="0.00050272983" iyy="0.015218160428" iyz="-0.000004273467" izz="0.011763977943"/>
    </inertial>
    <visual>
      <origin rpy="1.57079632679 0 0" xyz="0 0 0"/>
      <geometry>
        <cylinder length="0.034" radius="0.074792"/>
      </geometry>
      <material name="Wheel_r"/>
    </visual>
    <collision>
      <origin rpy="1.57079632679 0 0" xyz="0 0 0"/>
      <!-- rotation because cyl. geom primitive has symmetry axis in +x direction -->
      <geometry>
        <cylinder length="0.034" radius="0.074792"/>
      </geometry>
    </collision>
  </link>
  <gazebo reference="fl_caster_r_wheel_link">
    <mu1 value="100.0"/>
    <mu2 value="100.0"/>
    <kp value="1000000.0"/>
    <kd value="1.0"/>
    <material>IPA/LightGrey</material>
  </gazebo>
  <transmission name="fl_caster_r_wheel_trans" type="pr2_mechanism_model/SimpleTransmission">
    <actuator name="fl_caster_r_wheel_motor"/>
    <joint name="fl_caster_r_wheel_joint"/>
    <mechanicalReduction>-79.2380952381</mechanicalReduction>
  </transmission>
  <gazebo reference="fl_caster_rotation_link">
    <material value="PR2/caster_texture"/>
  </gazebo>
  <joint name="fr_caster_rotation_joint" type="continuous">
    <axis xyz="0 0 1"/>
    <limit effort="100" velocity="100"/>
    <!-- alpha tested velocity and effort limits -->
    <safety_controller k_velocity="10"/>
    <calibration rising="-0.785398163397"/>
    <dynamics damping="0.0" friction="0.0"/>
    <origin rpy="0 0 0" xyz="0.235 -0.185 0.075"/>
    <parent link="base_link"/>
    <child link="fr_caster_rotation_link"/>
  </joint>
  <link name="fr_caster_rotation_link">
    <inertial>
      <mass value="3.473082"/>
      <origin xyz="0 0 0.07"/>
      <inertia ixx="0.012411765597" ixy="-0.000711733678" ixz="0.00050272983" iyy="0.015218160428" iyz="-0.000004273467" izz="0.011763977943"/>
    </inertial>
    <visual>
      <!--origin xyz="0 0 0.085" rpy="0 0 0" /-->
      <!--modified by jie-->
      <origin rpy="0.0 0.0 0.0" xyz="0 0 0.002"/>
      <geometry>
        <!--mesh filename="package://cob_description/meshes/base/caster.stl" /-->
        <!--modified by jie-->
        <!--box size="0.192 0.164 0.013" /-->
        <box size="0.001 0.001 0.001"/>
      </geometry>
      <material name="Green"/>
    </visual>
    <collision>
      <origin rpy="0.0 0.0 0.0" xyz="0 0 0.002"/>
      <geometry>
        <box size="0.001 0.001 0.001"/>
      </geometry>
    </collision>
  </link>
  <transmission name="fr_caster_rotation_trans" type="pr2_mechanism_model/SimpleTransmission">
    <actuator name="fr_caster_rotation_motor"/>
    <joint name="fr_caster_rotation_joint"/>
    <mechanicalReduction>-79.2380952381</mechanicalReduction>
  </transmission>
  <joint name="fr_caster_r_wheel_joint" type="continuous">
    <axis xyz="0 1 0"/>
    <limit effort="100" velocity="100"/>
    <!-- alpha tested effort and velocity limits -->
    <safety_controller k_velocity="10"/>
    <dynamics damping="0.0" friction="0.0"/>
    <origin rpy="0 0 0" xyz="0 -0.0 0"/>
    <parent link="fr_caster_rotation_link"/>
    <child link="fr_caster_r_wheel_link"/>
  </joint>
  <link name="fr_caster_r_wheel_link">
    <inertial>
      <mass value="0.44036"/>
      <origin xyz="0 0 0"/>
      <inertia ixx="0.012411765597" ixy="-0.000711733678" ixz="0.00050272983" iyy="0.015218160428" iyz="-0.000004273467" izz="0.011763977943"/>
    </inertial>
    <visual>
      <origin rpy="1.57079632679 0 0" xyz="0 0 0"/>
      <geometry>
        <cylinder length="0.034" radius="0.074792"/>
      </geometry>
      <material name="Wheel_r"/>
    </visual>
    <collision>
      <origin rpy="1.57079632679 0 0" xyz="0 0 0"/>
      <!-- rotation because cyl. geom primitive has symmetry axis in +x direction -->
      <geometry>
        <cylinder length="0.034" radius="0.074792"/>
      </geometry>
    </collision>
  </link>
  <gazebo reference="fr_caster_r_wheel_link">
    <mu1 value="100.0"/>
    <mu2 value="100.0"/>
    <kp value="1000000.0"/>
    <kd value="1.0"/>
    <material>IPA/LightGrey</material>
  </gazebo>
  <transmission name="fr_caster_r_wheel_trans" type="pr2_mechanism_model/SimpleTransmission">
    <actuator name="fr_caster_r_wheel_motor"/>
    <joint name="fr_caster_r_wheel_joint"/>
    <mechanicalReduction>-79.2380952381</mechanicalReduction>
  </transmission>
  <gazebo reference="fr_caster_rotation_link">
    <material value="PR2/caster_texture"/>
  </gazebo>
  <joint name="bl_caster_rotation_joint" type="continuous">
    <axis xyz="0 0 1"/>
    <limit effort="100" velocity="100"/>
    <!-- alpha tested velocity and effort limits -->
    <safety_controller k_velocity="10"/>
    <calibration rising="2.35619449019"/>
    <dynamics damping="0.0" friction="0.0"/>
    <origin rpy="0 0 0" xyz="-0.235 0.185 0.075"/>
    <parent link="base_link"/>
    <child link="bl_caster_rotation_link"/>
  </joint>
  <link name="bl_caster_rotation_link">
    <inertial>
      <mass value="3.473082"/>
      <origin xyz="0 0 0.07"/>
      <inertia ixx="0.012411765597" ixy="-0.000711733678" ixz="0.00050272983" iyy="0.015218160428" iyz="-0.000004273467" izz="0.011763977943"/>
    </inertial>
    <visual>
      <!--origin xyz="0 0 0.085" rpy="0 0 0" /-->
      <!--modified by jie-->
      <origin rpy="0.0 0.0 0.0" xyz="0 0 0.002"/>
      <geometry>
        <!--mesh filename="package://cob_description/meshes/base/caster.stl" /-->
        <!--modified by jie-->
        <!--box size="0.192 0.164 0.013" /-->
        <box size="0.001 0.001 0.001"/>
      </geometry>
      <material name="Green"/>
    </visual>
    <collision>
      <origin rpy="0.0 0.0 0.0" xyz="0 0 0.002"/>
      <geometry>
        <box size="0.001 0.001 0.001"/>
      </geometry>
    </collision>
  </link>
  <transmission name="bl_caster_rotation_trans" type="pr2_mechanism_model/SimpleTransmission">
    <actuator name="bl_caster_rotation_motor"/>
    <joint name="bl_caster_rotation_joint"/>
    <mechanicalReduction>-79.2380952381</mechanicalReduction>
  </transmission>
  <joint name="bl_caster_r_wheel_joint" type="continuous">
    <axis xyz="0 1 0"/>
    <limit effort="100" velocity="100"/>
    <!-- alpha tested effort and velocity limits -->
    <safety_controller k_velocity="10"/>
    <dynamics damping="0.0" friction="0.0"/>
    <origin rpy="0 0 0" xyz="0 -0.0 0"/>
    <parent link="bl_caster_rotation_link"/>
    <child link="bl_caster_r_wheel_link"/>
  </joint>
  <link name="bl_caster_r_wheel_link">
    <inertial>
      <mass value="0.44036"/>
      <origin xyz="0 0 0"/>
      <inertia ixx="0.012411765597" ixy="-0.000711733678" ixz="0.00050272983" iyy="0.015218160428" iyz="-0.000004273467" izz="0.011763977943"/>
    </inertial>
    <visual>
      <origin rpy="1.57079632679 0 0" xyz="0 0 0"/>
      <geometry>
        <cylinder length="0.034" radius="0.074792"/>
      </geometry>
      <material name="Wheel_r"/>
    </visual>
    <collision>
      <origin rpy="1.57079632679 0 0" xyz="0 0 0"/>
      <!-- rotation because cyl. geom primitive has symmetry axis in +x direction -->
      <geometry>
        <cylinder length="0.034" radius="0.074792"/>
      </geometry>
    </collision>
  </link>
  <gazebo reference="bl_caster_r_wheel_link">
    <mu1 value="100.0"/>
    <mu2 value="100.0"/>
    <kp value="1000000.0"/>
    <kd value="1.0"/>
    <material>IPA/LightGrey</material>
  </gazebo>
  <transmission name="bl_caster_r_wheel_trans" type="pr2_mechanism_model/SimpleTransmission">
    <actuator name="bl_caster_r_wheel_motor"/>
    <joint name="bl_caster_r_wheel_joint"/>
    <mechanicalReduction>-79.2380952381</mechanicalReduction>
  </transmission>
  <gazebo reference="bl_caster_rotation_link">
    <material value="PR2/caster_texture"/>
  </gazebo>
  <joint name="br_caster_rotation_joint" type="continuous">
    <axis xyz="0 0 1"/>
    <limit effort="100" velocity="100"/>
    <!-- alpha tested velocity and effort limits -->
    <safety_controller k_velocity="10"/>
    <calibration rising="2.35619449019"/>
    <dynamics damping="0.0" friction="0.0"/>
    <origin rpy="0 0 0" xyz="-0.235 -0.185 0.075"/>
    <parent link="base_link"/>
    <child link="br_caster_rotation_link"/>
  </joint>
  <link name="br_caster_rotation_link">
    <inertial>
      <mass value="3.473082"/>
      <origin xyz="0 0 0.07"/>
      <inertia ixx="0.012411765597" ixy="-0.000711733678" ixz="0.00050272983" iyy="0.015218160428" iyz="-0.000004273467" izz="0.011763977943"/>
    </inertial>
    <visual>
      <!--origin xyz="0 0 0.085" rpy="0 0 0" /-->
      <!--modified by jie-->
      <origin rpy="0.0 0.0 0.0" xyz="0 0 0.002"/>
      <geometry>
        <!--mesh filename="package://cob_description/meshes/base/caster.stl" /-->
        <!--modified by jie-->
        <!--box size="0.192 0.164 0.013" /-->
        <box size="0.001 0.001 0.001"/>
      </geometry>
      <material name="Green"/>
    </visual>
    <collision>
      <origin rpy="0.0 0.0 0.0" xyz="0 0 0.002"/>
      <geometry>
        <box size="0.001 0.001 0.001"/>
      </geometry>
    </collision>
  </link>
  <transmission name="br_caster_rotation_trans" type="pr2_mechanism_model/SimpleTransmission">
    <actuator name="br_caster_rotation_motor"/>
    <joint name="br_caster_rotation_joint"/>
    <mechanicalReduction>-79.2380952381</mechanicalReduction>
  </transmission>
  <joint name="br_caster_r_wheel_joint" type="continuous">
    <axis xyz="0 1 0"/>
    <limit effort="100" velocity="100"/>
    <!-- alpha tested effort and velocity limits -->
    <safety_controller k_velocity="10"/>
    <dynamics damping="0.0" friction="0.0"/>
    <origin rpy="0 0 0" xyz="0 -0.0 0"/>
    <parent link="br_caster_rotation_link"/>
    <child link="br_caster_r_wheel_link"/>
  </joint>
  <link name="br_caster_r_wheel_link">
    <inertial>
      <mass value="0.44036"/>
      <origin xyz="0 0 0"/>
      <inertia ixx="0.012411765597" ixy="-0.000711733678" ixz="0.00050272983" iyy="0.015218160428" iyz="-0.000004273467" izz="0.011763977943"/>
    </inertial>
    <visual>
      <origin rpy="1.57079632679 0 0" xyz="0 0 0"/>
      <geometry>
        <cylinder length="0.034" radius="0.074792"/>
      </geometry>
      <material name="Wheel_r"/>
    </visual>
    <collision>
      <origin rpy="1.57079632679 0 0" xyz="0 0 0"/>
      <!-- rotation because cyl. geom primitive has symmetry axis in +x direction -->
      <geometry>
        <cylinder length="0.034" radius="0.074792"/>
      </geometry>
    </collision>
  </link>
  <gazebo reference="br_caster_r_wheel_link">
    <mu1 value="100.0"/>
    <mu2 value="100.0"/>
    <kp value="1000000.0"/>
    <kd value="1.0"/>
    <material>IPA/LightGrey</material>
  </gazebo>
  <transmission name="br_caster_r_wheel_trans" type="pr2_mechanism_model/SimpleTransmission">
    <actuator name="br_caster_r_wheel_motor"/>
    <joint name="br_caster_r_wheel_joint"/>
    <mechanicalReduction>-79.2380952381</mechanicalReduction>
  </transmission>
  <gazebo reference="br_caster_rotation_link">
    <material value="PR2/caster_texture"/>
  </gazebo>
  <gazebo reference="base_link">
    <selfCollide>true</selfCollide>
    <sensor name="base_contact_sensor" type="contact">
      <contact>
        <collision>base_link_geom</collision>
      </contact>
      <plugin filename="libgazebo_ros_bumper.so" name="base_gazebo_ros_bumper_controller">
        <alwaysOn>true</alwaysOn>
        <updateRate>100.0</updateRate>
        <bumperTopicName>base_bumper</bumperTopicName>
      </plugin>
    </sensor>
    <material>IPA/LightGrey</material>
  </gazebo>
  <gazebo>
    <plugin filename="libgazebo_ros_p3d.so" name="p3d_base_controller">
      <alwaysOn>true</alwaysOn>
      <updateRate>100.0</updateRate>
      <bodyName>base_link</bodyName>
      <topicName>base_pose_ground_truth</topicName>
      <gaussianNoise>0.01</gaussianNoise>
      <frameName>map</frameName>
      <xyzOffsets>25.7 25.7 0</xyzOffsets>
      <!-- initialize odometry for fake localization-->
      <rpyOffsets>0 0 0</rpyOffsets>
    </plugin>
    <canonicalBody>base_footprint</canonicalBody>
  </gazebo>
  <joint name="mpo_700_rack_joint" type="fixed">
    <parent link="base_link"/>
    <child link="kurtana_baseplate_link"/>
    <origin rpy="0 0 0" xyz="0 0 0.5"/>
  </joint>
  <!-- rack -->
  <link name="kurtana_baseplate_link">
    <visual>
      <origin rpy="0 0 0" xyz="0 0 0"/>
      <geometry>
        <box size="0.47 0.368 0.006"/>
      </geometry>
      <material name="grey">
        <color rgba="0.8 0.8 0.8 1"/>
      </material>
    </visual>
    <collision>
      <origin rpy="0 0 0" xyz="0 0 0"/>
      <geometry>
        <box size="0.47 0.368 0.006"/>
      </geometry>
    </collision>
    <inertial>
      <mass value="0.5"/>
      <origin xyz="0 0 0"/>
      <inertia ixx="0.005644164409" ixy="0.0" ixz="0.0" iyy="0.0092056629844" iyz="0.0" izz="0.0148468273946"/>
    </inertial>
  </link>
  <joint name="katana_baseplate_joint" type="fixed">
    <parent link="kurtana_baseplate_link"/>
    <child link="katana_baseplate_link"/>
    <origin xyz="0.05 0 0.009"/>
  </joint>
  <link name="katana_baseplate_link">
    <visual>
      <origin rpy="0 0 0" xyz="0 0 0"/>
      <geometry>
        <box size="0.156 0.156 0.012"/>
      </geometry>
      <material name="grey"/>
    </visual>
    <collision>
      <origin rpy="0 0 0" xyz="0 0 0"/>
      <geometry>
        <box size="0.156 0.156 0.012"/>
      </geometry>
    </collision>
    <inertial>
      <mass value="0.4"/>
      <origin xyz="0 0 0"/>
      <inertia ixx="0.0008159996736" ixy="0.0" ixz="0.0" iyy="0.0008159996736" iyz="0.0" izz="0.00162239935104"/>
    </inertial>
  </link>
  <joint name="kurtana_pole_joint" type="fixed">
    <parent link="kurtana_baseplate_link"/>
    <child link="kurtana_pole_link"/>
    <origin xyz="-0.18 0 0.35"/>
  </joint>
  <link name="kurtana_pole_link">
    <visual>
      <origin rpy="0 0 0" xyz="0 0 0"/>
      <geometry>
        <box size="0.03 0.03 0.7"/>
      </geometry>
      <material name="grey"/>
    </visual>
    <collision>
      <origin rpy="0 0 0" xyz="0 0 0"/>
      <geometry>
        <box size="0.03 0.03 0.7"/>
      </geometry>
    </collision>
    <inertial>
      <mass value="3.0"/>
      <origin xyz="0 0 0"/>
      <inertia ixx="0.12272495091" ixy="0.0" ixz="0.0" iyy="0.12272495091" iyz="0.0" izz="0.00044999982"/>
    </inertial>
  </link>
  <joint name="kurtana_microphone_joint" type="fixed">
    <parent link="kurtana_pole_link"/>
    <child link="kurtana_microphone_link"/>
    <origin xyz="0.06 -0.055 0.385"/>
  </joint>
  <link name="kurtana_microphone_link">
    <visual>
      <origin rpy="0 1.57079632679 0" xyz="0 0 0"/>
      <geometry>
        <cylinder length="0.24" radius="0.025"/>
      </geometry>
      <material name="black"/>
    </visual>
    <collision>
      <origin rpy="0 1.57079632679 0" xyz="0 0 0"/>
      <geometry>
        <cylinder length="0.24" radius="0.025"/>
      </geometry>
    </collision>
    <inertial>
      <mass value="0.3"/>
      <origin xyz="0 0 0"/>
      <inertia ixx="0.00148687440525" ixy="0.0" ixz="0.0" iyy="0.00148687440525" iyz="0.0" izz="9.375e-05"/>
    </inertial>
  </link>
  <joint name="kurtana_horizontal_square_bar_joint" type="fixed">
    <parent link="kurtana_pole_link"/>
    <child link="kurtana_horizontal_square_bar_link"/>
    <origin xyz="0.0715 0 0.335"/>
  </joint>
  <link name="kurtana_horizontal_square_bar_link">
    <visual>
      <origin rpy="0 0 0" xyz="0 0 0"/>
      <geometry>
        <box size="0.113 0.03 0.03"/>
      </geometry>
      <material name="grey"/>
    </visual>
    <collision>
      <origin rpy="0 0 0" xyz="0 0 0"/>
      <geometry>
        <box size="0.113 0.03 0.03"/>
      </geometry>
    </collision>
    <inertial>
      <mass value="0.1"/>
      <origin xyz="0 0 0"/>
      <inertia ixx="1.4999994e-05" ixy="0.0" ixz="0.0" iyy="0.00011390828777" iyz="0.0" izz="0.00011390828777"/>
    </inertial>
  </link>
  <joint name="kurtana_vertical_square_bar_joint" type="fixed">
    <parent link="kurtana_horizontal_square_bar_link"/>
    <child link="kurtana_vertical_square_bar_link"/>
    <origin xyz="0.0415 0 0.05875"/>
  </joint>
  <link name="kurtana_vertical_square_bar_link">
    <visual>
      <origin rpy="0 0 0" xyz="0 0 0"/>
      <geometry>
        <box size="0.03 0.03 0.0875"/>
      </geometry>
      <material name="grey"/>
    </visual>
    <collision>
      <origin rpy="0 0 0" xyz="0 0 0"/>
      <geometry>
        <box size="0.03 0.03 0.0875"/>
      </geometry>
    </collision>
    <inertial>
      <mass value="0.1"/>
      <origin xyz="0 0 0"/>
      <inertia ixx="7.13020548125e-05" ixy="0.0" ixz="0.0" iyy="7.13020548125e-05" iyz="0.0" izz="1.4999994e-05"/>
    </inertial>
  </link>
  <joint name="kurtana_roll_servo_joint" type="fixed">
    <parent link="kurtana_vertical_square_bar_link"/>
    <child link="kurtana_roll_servo_link"/>
    <origin xyz="0.049 0 0.01875"/>
  </joint>
  <link name="kurtana_roll_servo_link">
    <visual>
      <origin rpy="0 0 0" xyz="0 0 0"/>
      <geometry>
        <box size="0.068 0.032 0.05"/>
      </geometry>
      <material name="grey"/>
    </visual>
    <collision>
      <origin rpy="0 0 0" xyz="0 0 0"/>
      <geometry>
        <box size="0.068 0.032 0.05"/>
      </geometry>
    </collision>
    <inertial>
      <mass value="0.15"/>
      <origin xyz="0 0 0"/>
      <inertia ixx="4.404998238e-05" ixy="0.0" ixz="0.0" iyy="8.904996438e-05" iyz="0.0" izz="7.059997176e-05"/>
    </inertial>
  </link>
  <joint name="kurtana_roll_joint" type="revolute">
    <parent link="kurtana_roll_servo_link"/>
    <child link="kurtana_pitch_servo_link"/>
    <origin xyz="0.008 0 0.059"/>
    <axis xyz="0 0 1"/>
    <limit effort="1000.0" lower="-0.5" upper="0.5" velocity="2.0"/>
  </joint>
  <link name="kurtana_pitch_servo_link">
    <visual>
      <origin rpy="0 0 0" xyz="0 0 0"/>
      <geometry>
        <box size="0.032 0.05 0.068"/>
      </geometry>
      <material name="grey"/>
    </visual>
    <collision>
      <origin rpy="0 0 0" xyz="0 0 0"/>
      <geometry>
        <box size="0.032 0.05 0.068"/>
      </geometry>
    </collision>
    <inertial>
      <mass value="0.15"/>
      <origin xyz="0 0 0"/>
      <inertia ixx="8.904996438e-05" ixy="0.0" ixz="0.0" iyy="7.059997176e-05" iyz="0.0" izz="4.404998238e-05"/>
    </inertial>
  </link>
  <joint name="kurtana_pitch_joint" type="revolute">
    <parent link="kurtana_pitch_servo_link"/>
    <child link="kurtana_pitch_servo_movable_part_link"/>
    <origin rpy="0 0.045 0" xyz="0 0 0.008"/>
    <axis xyz="0 1 0"/>
    <limit effort="1000.0" lower="0.8" upper="1.2" velocity="2.0"/>
  </joint>
  <link name="kurtana_pitch_servo_movable_part_link">
    <visual>
      <origin rpy="0 0 0" xyz="0 0 0"/>
      <geometry>
        <box size="0.032 0.05 0.035"/>
      </geometry>
      <material name="grey"/>
    </visual>
    <collision>
      <origin rpy="0 0 0" xyz="0 0 0"/>
      <geometry>
        <box size="0.032 0.05 0.035"/>
      </geometry>
    </collision>
    <inertial>
      <mass value="0.15"/>
      <origin xyz="0 0 0"/>
      <inertia ixx="4.6562481375e-05" ixy="0.0" ixz="0.0" iyy="2.8112488755e-05" iyz="0.0" izz="4.404998238e-05"/>
    </inertial>
  </link>
  <joint name="kurtana_kinect_mounting_plate_joint" type="fixed">
    <parent link="kurtana_pitch_servo_movable_part_link"/>
    <child link="kurtana_kinect_mounting_plate_link"/>
    <origin rpy="0 0 0" xyz="0 0 0.021"/>
  </joint>
  <link name="kurtana_kinect_mounting_plate_link">
    <visual>
      <origin rpy="0 0 0" xyz="0 0 0"/>
      <geometry>
        <box size="0.045 0.17 0.007"/>
      </geometry>
      <material name="grey"/>
    </visual>
    <collision>
      <origin rpy="0 0 0" xyz="0 0 0"/>
      <geometry>
        <box size="0.045 0.17 0.007"/>
      </geometry>
    </collision>
    <inertial>
      <mass value="0.05"/>
      <origin xyz="0 0 0"/>
      <inertia ixx="0.000120620785085" ixy="0.0" ixz="0.0" iyy="8.64166321e-06" iyz="0.0" izz="0.000128854115125"/>
    </inertial>
  </link>
  <transmission name="kurtana_stretch_trans" type="pr2_mechanism_model/SimpleTransmission">
    <actuator name="kurtana_stretch_motor"/>
    <joint name="kurtana_stretch_joint"/>
    <mechanicalReduction>1</mechanicalReduction>
    <motorTorqueConstant>1</motorTorqueConstant>
  </transmission>
  <transmission name="kurtana_roll_trans" type="pr2_mechanism_model/SimpleTransmission">
    <actuator name="kurtana_roll_motor"/>
    <joint name="kurtana_roll_joint"/>
    <mechanicalReduction>1</mechanicalReduction>
    <motorTorqueConstant>1</motorTorqueConstant>
  </transmission>
  <transmission name="kurtana_pitch_trans" type="pr2_mechanism_model/SimpleTransmission">
    <actuator name="kurtana_pitch_motor"/>
    <joint name="kurtana_pitch_joint"/>
    <mechanicalReduction>1</mechanicalReduction>
    <motorTorqueConstant>1</motorTorqueConstant>
  </transmission>
  <gazebo reference="kurtana_rackplate_link">
    <material value="PR2/Grey"/>
  </gazebo>
  <gazebo reference="kurtana_baseplate_link">
    <material value="PR2/Grey"/>
  </gazebo>
  <gazebo reference="kurtana_pole_link">
    <material value="PR2/Grey"/>
  </gazebo>
  <gazebo reference="kurtana_innerpole_stretch_link">
    <material value="PR2/Grey"/>
  </gazebo>
  <gazebo reference="kurtana_poletop_roll_link">
    <material value="PR2/Grey"/>
  </gazebo>
  <gazebo reference="kurtana_pitchpole_link">
    <material value="PR2/Grey"/>
  </gazebo>
  <link name="kinect_link">
    <visual>
      <origin rpy="0 0 0" xyz="0 0 0"/>
      <geometry>
        <mesh filename="package://pr2_description/meshes/sensors/kinect_v0/kinect.dae" scale="0.001 0.001 0.001"/>
      </geometry>
    </visual>
    <collision>
      <origin rpy="0 0 0" xyz="-0.0315 0 -0.017"/>
      <geometry>
        <box size="0.0730 0.2760 0.0720"/>
      </geometry>
    </collision>
    <inertial>
      <mass value="0.43"/>
      <origin xyz="0 0 0"/>
      <inertia ixx="0.00291539883384" ixy="0.0" ixz="0.0" iyy="0.000376715682647" iyz="0.0" izz="0.0029205946651"/>
    </inertial>
  </link>
  <joint name="kinect_depth_joint" type="fixed">
    <origin rpy="0 0 0" xyz="0 0.018 0"/>
    <parent link="kinect_link"/>
    <child link="kinect_depth_frame"/>
  </joint>
  <link name="kinect_depth_frame">
    <inertial>
      <mass value="0.000001"/>
      <origin xyz="0 0 0"/>
      <inertia ixx="0.0001" ixy="0.0" ixz="0.0" iyy="0.0001" iyz="0.0" izz="0.0001"/>
    </inertial>
  </link>
  <joint name="kinect_depth_optical_joint" type="fixed">
    <origin rpy="-1.57079632679 0 -1.57079632679" xyz="0 0 0"/>
    <parent link="kinect_depth_frame"/>
    <child link="kinect_depth_optical_frame"/>
  </joint>
  <link name="kinect_depth_optical_frame">
    <inertial>
      <mass value="0.000001"/>
      <origin xyz="0 0 0"/>
      <inertia ixx="0.0001" ixy="0.0" ixz="0.0" iyy="0.0001" iyz="0.0" izz="0.0001"/>
    </inertial>
  </link>
  <gazebo reference="kinect_depth_frame">
    <sensor name="kinect_depth_frame_ir_sensor" type="depth">
      <always_on>true</always_on>
      <update_rate>1.0</update_rate>
      <camera>
        <horizontal_fov>0.994837673637</horizontal_fov>
        <image>
          <format>L8</format>
          <width>640</width>
          <height>480</height>
        </image>
        <clip>
          <near>0.01</near>
          <far>5</far>
        </clip>
      </camera>
      <plugin filename="libgazebo_ros_openni_kinect.so" name="kinect_depth_frame_controller">
        <alwaysOn>true</alwaysOn>
        <updateRate>1.0</updateRate>
        <cameraName>kinect_ir</cameraName>
        <imageTopicName>/kinect/depth/image_raw</imageTopicName>
        <cameraInfoTopicName>/kinect/depth/camera_info</cameraInfoTopicName>
        <depthImageTopicName>/kinect/depth/image_raw</depthImageTopicName>
        <depthImageInfoTopicName>/kinect/depth/camera_info</depthImageInfoTopicName>
        <pointCloudTopicName>/kinect/depth/points</pointCloudTopicName>
        <frameName>kinect_depth_optical_frame</frameName>
        <pointCloudCutoff>0.5</pointCloudCutoff>
        <distortionK1>0.00000001</distortionK1>
        <distortionK2>0.00000001</distortionK2>
        <distortionK3>0.00000001</distortionK3>
        <distortionT1>0.00000001</distortionT1>
        <distortionT2>0.00000001</distortionT2>
      </plugin>
    </sensor>
    <material value="Gazebo/Red"/>
  </gazebo>
  <joint name="kinect_rgb_joint" type="fixed">
    <origin rpy="0 0 0" xyz="0 -0.005 0"/>
    <parent link="kinect_link"/>
    <child link="kinect_rgb_frame"/>
  </joint>
  <link name="kinect_rgb_frame">
    <inertial>
      <mass value="0.000001"/>
      <origin xyz="0 0 0"/>
      <inertia ixx="0.0001" ixy="0.0" ixz="0.0" iyy="0.0001" iyz="0.0" izz="0.0001"/>
    </inertial>
  </link>
  <joint name="kinect_rgb_optical_joint" type="fixed">
    <origin rpy="-1.57079632679 0 -1.57079632679" xyz="0 0 0"/>
    <parent link="kinect_rgb_frame"/>
    <child link="kinect_rgb_optical_frame"/>
  </joint>
  <link name="kinect_rgb_optical_frame">
    <inertial>
      <mass value="0.000001"/>
      <origin xyz="0 0 0"/>
      <inertia ixx="0.0001" ixy="0.0" ixz="0.0" iyy="0.0001" iyz="0.0" izz="0.0001"/>
    </inertial>
  </link>
  <gazebo reference="kinect_rgb_frame">
    <sensor name="kinect_rgb_sensor" type="depth">
      <always_on>true</always_on>
      <update_rate>1.0</update_rate>
      <camera>
        <horizontal_fov>0.994837673637</horizontal_fov>
        <image>
          <format>R8G8B8</format>
          <width>640</width>
          <height>480</height>
        </image>
        <clip>
          <near>0.01</near>
          <far>5</far>
        </clip>
      </camera>
      <plugin filename="libgazebo_ros_openni_kinect.so" name="kinect_rgb_frame_controller">
        <alwaysOn>true</alwaysOn>
        <updateRate>1.0</updateRate>
        <cameraName>kinect_rgb</cameraName>
        <imageTopicName>/kinect/rgb/image_raw</imageTopicName>
        <cameraInfoTopicName>/kinect/rgb/camera_info</cameraInfoTopicName>
        <pointCloudTopicName>/kinect/depth_registered/points</pointCloudTopicName>
        <frameName>kinect_rgb_optical_frame</frameName>
        <pointCloudCutoff>0.5</pointCloudCutoff>
        <distortionK1>0.00000001</distortionK1>
        <distortionK2>0.00000001</distortionK2>
        <distortionK3>0.00000001</distortionK3>
        <distortionT1>0.00000001</distortionT1>
        <distortionT2>0.00000001</distortionT2>
      </plugin>
    </sensor>
    <material value="Gazebo/Red"/>
  </gazebo>
  <joint name="kurtana_kinect_joint" type="fixed">
    <parent link="kurtana_kinect_mounting_plate_link"/>
    <child link="kinect_link"/>
    <origin rpy="0 0 0" xyz="0.03 0.0 0.018"/>
  </joint>
  <joint name="kurtana_baseplate_katana_baseplate_joint" type="fixed">
    <parent link="katana_baseplate_link"/>
    <child link="jaco_base_link"/>
    <origin rpy="0 0 0" xyz="0 0 0.05"/>
  </joint>
  <!-- arm-->
  <material name="JacoGrey">
    <color rgba="0.2 0.2 0.9 1.0"/>
  </material>
  <link name="jaco_base_link">
    <visual>
      <material name="JacoGrey"/>
      <origin rpy="0 0 1.57079632679" xyz="0 0 0"/>
      <geometry>
        <mesh filename="package://jaco_description/meshes/jaco_base_joint.stl"/>
      </geometry>
    </visual>
    <collision>
      <origin rpy="0 0 1.57079632679" xyz="0 0 0"/>
      <geometry>
        <mesh filename="package://jaco_description/meshes/jaco_base_joint.stl"/>
      </geometry>
    </collision>
  </link>
  <joint name="jaco_shoulder_yaw_joint" type="revolute">
    <origin rpy="0 0 0" xyz="0 0 0.2102"/>
    <axis rpy="0 0 0" xyz="0 0 1"/>
    <parent link="jaco_base_link"/>
    <child link="jaco_shoulder_link"/>
    <limit effort="1" lower="-3.14159265359" upper="3.14159265359" velocity="3.14159265359"/>
  </joint>
  <link name="jaco_shoulder_link">
    <visual>
      <material name="JacoGrey"/>
      <origin rpy="1.57079632679 -1.57079632679 0" xyz="0 0 0"/>
      <geometry>
        <mesh filename="package://jaco_description/meshes/jaco_shoulder_yaw_joint.stl"/>
      </geometry>
    </visual>
    <collision>
      <origin rpy="1.57079632679 -1.57079632679 0" xyz="0 0 0"/>
      <geometry>
        <mesh filename="package://jaco_description/meshes/jaco_shoulder_yaw_joint.stl"/>
      </geometry>
    </collision>
  </link>
  <joint name="jaco_shoulder_pitch_joint" type="revolute">
    <origin rpy="-1.57079632679 0 0" xyz="0 0 0"/>
    <axis xyz="0 0 1"/>
    <parent link="jaco_shoulder_link"/>
    <child link="jaco_upper_arm_link"/>
    <limit effort="1" lower="-3.14159265359" upper="3.14159265359" velocity="3.14159265359"/>
  </joint>
  <link name="jaco_upper_arm_link">
    <visual>
      <material name="JacoGrey"/>
      <origin rpy="0 0 -1.57079632679" xyz="0 0 0"/>
      <geometry>
        <mesh filename="package://jaco_description/meshes/jaco_shoulder_pitch_joint.stl"/>
      </geometry>
    </visual>
    <collision>
      <origin rpy="0 0 -1.57079632679" xyz="0 0 0"/>
      <geometry>
        <mesh filename="package://jaco_description/meshes/jaco_shoulder_pitch_joint.stl"/>
      </geometry>
    </collision>
  </link>
  <joint name="jaco_elbow_pitch_joint" type="revolute">
    <origin rpy="0 0 0" xyz="0.41 0 0.012"/>
    <axis xyz="0 0 1"/>
    <parent link="jaco_upper_arm_link"/>
    <child link="jaco_lower_arm_link"/>
    <limit effort="1" lower="-3.14159265359" upper="3.14159265359" velocity="3.14159265359"/>
  </joint>
  <link name="jaco_lower_arm_link">
    <visual>
      <material name="JacoGrey"/>
      <origin rpy="3.14159265359 0 3.14159265359" xyz="0 0 -0.012"/>
      <geometry>
        <mesh filename="package://jaco_description/meshes/jaco_elbow_pitch_joint.stl"/>
      </geometry>
    </visual>
    <collision>
      <origin rpy="3.14159265359 0 3.14159265359" xyz="0 0 -0.012"/>
      <geometry>
        <mesh filename="package://jaco_description/meshes/jaco_elbow_pitch_joint.stl"/>
      </geometry>
    </collision>
  </link>
  <joint name="jaco_elbow_roll_joint" type="revolute">
    <origin rpy="-1.57079632679 0 0" xyz="0 0.249276823007 0 "/>
    <axis xyz="0 0 1"/>
    <parent link="jaco_lower_arm_link"/>
    <child link="jaco_lower_arm_roll_link"/>
    <limit effort="1" lower="-3.14159265359" upper="3.14159265359" velocity="3.14159265359"/>
  </joint>
  <link name="jaco_lower_arm_roll_link">
    <visual>
      <material name="JacoGrey"/>
      <origin rpy="3.14159265359 0 1.57079632679" xyz="0 0 -0.0422768230075"/>
      <geometry>
        <mesh filename="package://jaco_description/meshes/jaco_elbow_roll_joint.stl"/>
      </geometry>
    </visual>
    <collision>
      <origin rpy="3.14159265359 0 1.57079632679" xyz="0 0 -0.0422768230075"/>
      <geometry>
        <mesh filename="package://jaco_description/meshes/jaco_elbow_roll_joint.stl"/>
      </geometry>
    </collision>
  </link>
  <joint name="jaco_wrist_roll_joint" type="revolute">
    <origin rpy="0.959931088597 0 0" xyz="0 -0.0692622919853 0.0484979789618"/>
    <axis xyz="0 0 1"/>
    <parent link="jaco_lower_arm_roll_link"/>
    <child link="jaco_wrist_link"/>
    <limit effort="1" lower="-3.14159265359" upper="3.14159265359" velocity="3.14159265359"/>
  </joint>
  <link name="jaco_wrist_link">
    <visual>
      <material name="JacoGrey"/>
      <origin rpy="0 3.14159265359 -1.57079632679" xyz="0 0 -0.0422768230075"/>
      <geometry>
        <mesh filename="package://jaco_description/meshes/jaco_wrist_roll_joint.stl"/>
      </geometry>
    </visual>
    <collision>
      <origin rpy="0 3.14159265359 -1.57079632679" xyz="0 0 -0.0422768230075"/>
      <geometry>
        <mesh filename="package://jaco_description/meshes/jaco_wrist_roll_joint.stl"/>
      </geometry>
    </collision>
  </link>
  <joint name="jaco_hand_roll_joint" type="revolute">
    <origin rpy="0.959931088597 0 0" xyz="0 -0.186174274186 0.130360630206"/>
    <axis xyz="0 0 1"/>
    <parent link="jaco_wrist_link"/>
    <child link="jaco_hand_link"/>
    <limit effort="1" lower="-3.14159265359" upper="3.14159265359" velocity="3.14159265359"/>
  </joint>
  <link name="jaco_hand_link">
    <visual>
      <material name="JacoGrey"/>
      <origin rpy="0 0 -3.14159265359" xyz="0 0 -0.185"/>
      <geometry>
        <mesh filename="package://jaco_description/meshes/jaco_hand_roll_joint.stl"/>
      </geometry>
    </visual>
    <collision>
      <origin rpy="0 0 -3.14159265359" xyz="0 0 -0.185"/>
      <geometry>
        <mesh filename="package://jaco_description/meshes/jaco_hand_roll_joint.stl"/>
      </geometry>
    </collision>
  </link>
  <joint name="jaco_finger_1_joint" type="revolute">
    <origin rpy="0 -0.448798950513 0" xyz="-0.036 0.021 -0.07"/>
    <axis xyz="0 1 0"/>
    <parent link="jaco_hand_link"/>
    <child link="jaco_finger_1_link"/>
    <limit effort="1" lower="-3.14159265359" upper="3.14159265359" velocity="3.14159265359"/>
  </joint>
  <link name="jaco_finger_1_link">
    <visual>
      <material name="JacoGrey"/>
      <origin rpy="0 0 0" xyz="0 0 0"/>
      <geometry>
        <mesh filename="package://jaco_description/meshes/finger.dae"/>
      </geometry>
    </visual>
    <collision>
      <origin rpy="0 0 0" xyz="0 0 0"/>
      <geometry>
        <mesh filename="package://jaco_description/meshes/finger.dae"/>
      </geometry>
    </collision>
  </link>
  <joint name="jaco_finger_2_joint" type="revolute">
    <origin rpy="0 -0.448798950513 -3.14159265359" xyz="0.036 -0 -0.07"/>
    <axis xyz="0 1 0"/>
    <parent link="jaco_hand_link"/>
    <child link="jaco_finger_2_link"/>
    <limit effort="1" lower="-3.14159265359" upper="3.14159265359" velocity="3.14159265359"/>
  </joint>
  <link name="jaco_finger_2_link">
    <visual>
      <material name="JacoGrey"/>
      <origin rpy="0 0 0" xyz="0 0 0"/>
      <geometry>
        <mesh filename="package://jaco_description/meshes/finger.dae"/>
      </geometry>
    </visual>
    <collision>
      <origin rpy="0 0 0" xyz="0 0 0"/>
      <geometry>
        <mesh filename="package://jaco_description/meshes/finger.dae"/>
      </geometry>
    </collision>
  </link>
  <joint name="jaco_finger_3_joint" type="revolute">
    <origin rpy="0 -0.448798950513 0" xyz="-0.036 -0.021 -0.07"/>
    <axis xyz="0 1 0"/>
    <parent link="jaco_hand_link"/>
    <child link="jaco_finger_3_link"/>
    <limit effort="1" lower="-3.14159265359" upper="3.14159265359" velocity="3.14159265359"/>
  </joint>
  <link name="jaco_finger_3_link">
    <visual>
      <material name="JacoGrey"/>
      <origin rpy="0 0 0" xyz="0 0 0"/>
      <geometry>
        <mesh filename="package://jaco_description/meshes/finger.dae"/>
      </geometry>
    </visual>
    <collision>
      <origin rpy="0 0 0" xyz="0 0 0"/>
      <geometry>
        <mesh filename="package://jaco_description/meshes/finger.dae"/>
      </geometry>
    </collision>
  </link>
</robot>

