<?xml version="1.0" ?>
<!-- =================================================================================== -->
<!-- |    This document was autogenerated by xacro from /home/sp/groovy_rosbuild_workspace/kurt_driver/kurt_description/robots/kurtana.urdf.xacro | -->
<!-- |    EDITING THIS FILE BY HAND IS NOT RECOMMENDED                                 | -->
<!-- =================================================================================== -->
<robot name="kurtana" xmlns:controller="http://playerstage.sourceforge.net/gazebo/xmlschema/#controller" xmlns:interface="http://playerstage.sourceforge.net/gazebo/xmlschema/#interface" xmlns:sensor="http://playerstage.sourceforge.net/gazebo/xmlschema/#sensor" xmlns:xacro="http://ros.org/wiki/xacro">
  <!-- distance from base_link to top of cover surface -->
  <link name="ultrasound_front">
    <visual>
      <origin rpy="0 1.57079632679 0" xyz="0 0 0"/>
      <geometry>
        <cylinder length="0.005" radius="0.01"/>
      </geometry>
      <material name="yellow">
        <color rgba="1.0 1.0 0.0 1.0"/>
      </material>
    </visual>
    <collision>
      <origin rpy="0 1.57079632679 0" xyz="0 0 0"/>
      <geometry>
        <cylinder length="0.005" radius="0.01"/>
      </geometry>
    </collision>
    <inertial>
      <mass value="0.01"/>
      <origin xyz="0 0 0"/>
      <inertia ixx="2.70833225e-07" ixy="0.0" ixz="0.0" iyy="2.70833225e-07" iyz="0.0" izz="5e-07"/>
    </inertial>
  </link>
  <link name="ir_right_front">
    <visual>
      <origin rpy="0 0 0" xyz="0 0 0"/>
      <geometry>
        <box size="0.01 0.02 0.01"/>
      </geometry>
      <material name="light_grey">
        <color rgba="0.9 0.9 0.9 1.0"/>
      </material>
    </visual>
    <collision>
      <origin rpy="0 0 0" xyz="0 0 0"/>
      <geometry>
        <box size="0.01 0.02 0.01"/>
      </geometry>
    </collision>
    <inertial>
      <mass value="0.01"/>
      <origin xyz="0 0 0"/>
      <inertia ixx="4.166665e-07" ixy="0.0" ixz="0.0" iyy="1.666666e-07" iyz="0.0" izz="4.166665e-07"/>
    </inertial>
  </link>
  <link name="ir_right">
    <visual>
      <origin rpy="0 0 0" xyz="0 0 0"/>
      <geometry>
        <box size="0.01 0.02 0.01"/>
      </geometry>
      <material name="light_grey">
        <color rgba="0.9 0.9 0.9 1.0"/>
      </material>
    </visual>
    <collision>
      <origin rpy="0 0 0" xyz="0 0 0"/>
      <geometry>
        <box size="0.01 0.02 0.01"/>
      </geometry>
    </collision>
    <inertial>
      <mass value="0.01"/>
      <origin xyz="0 0 0"/>
      <inertia ixx="4.166665e-07" ixy="0.0" ixz="0.0" iyy="1.666666e-07" iyz="0.0" izz="4.166665e-07"/>
    </inertial>
  </link>
  <link name="ir_right_back">
    <visual>
      <origin rpy="0 0 0" xyz="0 0 0"/>
      <geometry>
        <box size="0.01 0.02 0.01"/>
      </geometry>
      <material name="light_grey">
        <color rgba="0.9 0.9 0.9 1.0"/>
      </material>
    </visual>
    <collision>
      <origin rpy="0 0 0" xyz="0 0 0"/>
      <geometry>
        <box size="0.01 0.02 0.01"/>
      </geometry>
    </collision>
    <inertial>
      <mass value="0.01"/>
      <origin xyz="0 0 0"/>
      <inertia ixx="4.166665e-07" ixy="0.0" ixz="0.0" iyy="1.666666e-07" iyz="0.0" izz="4.166665e-07"/>
    </inertial>
  </link>
  <link name="ir_back">
    <visual>
      <origin rpy="0 0 0" xyz="0 0 0"/>
      <geometry>
        <box size="0.01 0.02 0.01"/>
      </geometry>
      <material name="light_grey">
        <color rgba="0.9 0.9 0.9 1.0"/>
      </material>
    </visual>
    <collision>
      <origin rpy="0 0 0" xyz="0 0 0"/>
      <geometry>
        <box size="0.01 0.02 0.01"/>
      </geometry>
    </collision>
    <inertial>
      <mass value="0.01"/>
      <origin xyz="0 0 0"/>
      <inertia ixx="4.166665e-07" ixy="0.0" ixz="0.0" iyy="1.666666e-07" iyz="0.0" izz="4.166665e-07"/>
    </inertial>
  </link>
  <link name="ir_left_back">
    <visual>
      <origin rpy="0 0 0" xyz="0 0 0"/>
      <geometry>
        <box size="0.01 0.02 0.01"/>
      </geometry>
      <material name="light_grey">
        <color rgba="0.9 0.9 0.9 1.0"/>
      </material>
    </visual>
    <collision>
      <origin rpy="0 0 0" xyz="0 0 0"/>
      <geometry>
        <box size="0.01 0.02 0.01"/>
      </geometry>
    </collision>
    <inertial>
      <mass value="0.01"/>
      <origin xyz="0 0 0"/>
      <inertia ixx="4.166665e-07" ixy="0.0" ixz="0.0" iyy="1.666666e-07" iyz="0.0" izz="4.166665e-07"/>
    </inertial>
  </link>
  <link name="ir_left">
    <visual>
      <origin rpy="0 0 0" xyz="0 0 0"/>
      <geometry>
        <box size="0.01 0.02 0.01"/>
      </geometry>
      <material name="light_grey">
        <color rgba="0.9 0.9 0.9 1.0"/>
      </material>
    </visual>
    <collision>
      <origin rpy="0 0 0" xyz="0 0 0"/>
      <geometry>
        <box size="0.01 0.02 0.01"/>
      </geometry>
    </collision>
    <inertial>
      <mass value="0.01"/>
      <origin xyz="0 0 0"/>
      <inertia ixx="4.166665e-07" ixy="0.0" ixz="0.0" iyy="1.666666e-07" iyz="0.0" izz="4.166665e-07"/>
    </inertial>
  </link>
  <link name="ir_left_front">
    <visual>
      <origin rpy="0 0 0" xyz="0 0 0"/>
      <geometry>
        <box size="0.01 0.02 0.01"/>
      </geometry>
      <material name="light_grey">
        <color rgba="0.9 0.9 0.9 1.0"/>
      </material>
    </visual>
    <collision>
      <origin rpy="0 0 0" xyz="0 0 0"/>
      <geometry>
        <box size="0.01 0.02 0.01"/>
      </geometry>
    </collision>
    <inertial>
      <mass value="0.01"/>
      <origin xyz="0 0 0"/>
      <inertia ixx="4.166665e-07" ixy="0.0" ixz="0.0" iyy="1.666666e-07" iyz="0.0" izz="4.166665e-07"/>
    </inertial>
  </link>
  <joint name="base_ultrasound_front" type="fixed">
    <parent link="base_link"/>
    <child link="ultrasound_front"/>
    <origin rpy="0 0 0" xyz="0.217 0 0"/>
  </joint>
  <joint name="base_ir_right_front" type="fixed">
    <parent link="base_link"/>
    <child link="ir_right_front"/>
    <origin rpy="0 0 5.49778714378" xyz="0.203 -0.153 0"/>
  </joint>
  <joint name="base_ir_right" type="fixed">
    <parent link="base_link"/>
    <child link="ir_right"/>
    <origin rpy="0 0 4.71238898038" xyz="0 -0.165 0"/>
  </joint>
  <joint name="base_ir_right_back" type="fixed">
    <parent link="base_link"/>
    <child link="ir_right_back"/>
    <origin rpy="0 0 3.92699081699" xyz="-0.203 -0.153 0"/>
  </joint>
  <joint name="base_ir_back" type="fixed">
    <parent link="base_link"/>
    <child link="ir_back"/>
    <origin rpy="0 0 3.14159265359" xyz="-0.217 0 0"/>
  </joint>
  <joint name="base_ir_left_back" type="fixed">
    <parent link="base_link"/>
    <child link="ir_left_back"/>
    <origin rpy="0 0 2.35619449019" xyz="-0.203 0.153 0"/>
  </joint>
  <joint name="base_ir_left" type="fixed">
    <parent link="base_link"/>
    <child link="ir_left"/>
    <origin rpy="0 0 1.57079632679" xyz="0 0.165 0"/>
  </joint>
  <joint name="base_ir_left_front" type="fixed">
    <parent link="base_link"/>
    <child link="ir_left_front"/>
    <origin rpy="0 0 0.785398163397" xyz="0.203 0.153 0"/>
  </joint>
  <link name="base_link">
    <visual>
      <origin rpy="0 0 0" xyz="0 0 0"/>
      <geometry>
        <mesh filename="package://kurt_description/meshes/kurt_base_outdoor.stl"/>
      </geometry>
      <material name="red">
        <color rgba="1 0 0 1"/>
      </material>
    </visual>
    <collision>
      <origin rpy="0 0 0" xyz="0 0 0"/>
      <geometry>
        <mesh filename="package://kurt_description/meshes/kurt_base_outdoor.stl"/>
      </geometry>
    </collision>
    <!-- <visual>
      <geometry>
        <box size=".43 .325 .215" />
      </geometry>
      <material name="red" >
        <color rgba="1 0 0 1" />
      </material>
    </visual> -->
    <inertial>
      <mass value="15.6"/>
      <origin xyz="0.0 0.0 -0.040426445"/>
      <inertia ixx="0.1185264288" ixy="0.0" ixz="0.0" iyy="0.1927711968" iyz="0.0" izz="0.2402081448"/>
    </inertial>
  </link>
  <gazebo reference="base_link">
    <material value="Gazebo/Red"/>
  </gazebo>
  <gazebo>
    <plugin filename="libgazebo_ros_kurt.so" name="kurt_controller">
      <alwaysOn>true</alwaysOn>
      <cmd_vel_topic_name>cmd_vel</cmd_vel_topic_name>
      <odom_topic_name>odom</odom_topic_name>
      <joint_states_topic_name>joint_states</joint_states_topic_name>
      <left_front_wheel_joint>left_front_wheel_joint</left_front_wheel_joint>
      <left_middle_wheel_joint>left_middle_wheel_joint</left_middle_wheel_joint>
      <left_rear_wheel_joint>left_rear_wheel_joint</left_rear_wheel_joint>
      <right_front_wheel_joint>right_front_wheel_joint</right_front_wheel_joint>
      <right_middle_wheel_joint>right_middle_wheel_joint</right_middle_wheel_joint>
      <right_rear_wheel_joint>right_rear_wheel_joint</right_rear_wheel_joint>
      <wheel_separation>0.39</wheel_separation>
      <wheel_diameter>0.16488</wheel_diameter>
      <turning_adaptation>0.64</turning_adaptation>
      <torque>4.0</torque>
      <max_velocity>1.3</max_velocity>
      <updateRate>40.0</updateRate>
    </plugin>
  </gazebo>
  <gazebo>
    <plugin filename="libgazebo_ros_p3d.so" name="base_footprint_controller">
      <alwaysOn>true</alwaysOn>
      <updateRate>30.0</updateRate>
      <bodyName>base_footprint</bodyName>
      <topicName>base_footprint_pose_ground_truth</topicName>
      <gaussianNoise>0.0</gaussianNoise>
      <frameName>map</frameName>
      <interface:position name="base_footprint_p3d_position_iface"/>
    </plugin>
  </gazebo>
  <gazebo>
    <plugin filename="libgazebo_ros_imu.so" name="imu_controller">
      <alwaysOn>true</alwaysOn>
      <updateRate>100.0</updateRate>
      <bodyName>base_link</bodyName>
      <topicName>imu</topicName>
      <gaussianNoise>2.89e-08</gaussianNoise>
      <xyzOffsets>0 0 0</xyzOffsets>
      <rpyOffsets>0 0 0</rpyOffsets>
      <interface:position name="imu_position"/>
    </plugin>
  </gazebo>
  <link name="left_front_wheel_link">
    <visual>
      <origin rpy="0 0 0" xyz="0 0 0"/>
      <geometry>
        <mesh filename="package://kurt_description/meshes/kurt_wheel_outdoor.stl"/>
      </geometry>
      <material name="blackish">
        <color rgba="0.1 0.1 0.1 1"/>
      </material>
    </visual>
    <collision>
      <origin rpy="0 0 0" xyz="0 0 0"/>
      <geometry>
        <mesh filename="package://kurt_description/meshes/kurt_wheel_outdoor.stl"/>
        <!-- <cylinder length="${wheel_width}" radius="${wheel_radius}" /> -->
      </geometry>
    </collision>
    <inertial>
      <mass value="0.15"/>
      <origin xyz="0 0 0"/>
      <inertia ixx="0.000177810" ixy="0.0" ixz="0.0" iyy="0.000332643" iyz="0.0" izz="0.000177810"/>
    </inertial>
  </link>
  <joint name="left_front_wheel_joint" type="continuous">
    <origin rpy="0 0 0" xyz="0.14 0.14 -0.107"/>
    <parent link="base_link"/>
    <child link="left_front_wheel_link"/>
    <axis xyz="0 1 0"/>
  </joint>
  <gazebo reference="kurt_wheel_left_front">
    <material value="Gazebo/Grey"/>
  </gazebo>
  <link name="left_middle_wheel_link">
    <visual>
      <origin rpy="0 0 0" xyz="0 0 0"/>
      <geometry>
        <mesh filename="package://kurt_description/meshes/kurt_wheel_outdoor.stl"/>
      </geometry>
      <material name="blackish">
        <color rgba="0.1 0.1 0.1 1"/>
      </material>
    </visual>
    <collision>
      <origin rpy="0 0 0" xyz="0 0 0"/>
      <geometry>
        <mesh filename="package://kurt_description/meshes/kurt_wheel_outdoor.stl"/>
        <!-- <cylinder length="${wheel_width}" radius="${wheel_radius}" /> -->
      </geometry>
    </collision>
    <inertial>
      <mass value="0.15"/>
      <origin xyz="0 0 0"/>
      <inertia ixx="0.000177810" ixy="0.0" ixz="0.0" iyy="0.000332643" iyz="0.0" izz="0.000177810"/>
    </inertial>
  </link>
  <joint name="left_middle_wheel_joint" type="continuous">
    <origin rpy="0 0 0" xyz="0 0.195 -0.107"/>
    <parent link="base_link"/>
    <child link="left_middle_wheel_link"/>
    <axis xyz="0 1 0"/>
  </joint>
  <gazebo reference="kurt_wheel_left_middle">
    <material value="Gazebo/Grey"/>
  </gazebo>
  <link name="left_rear_wheel_link">
    <visual>
      <origin rpy="0 0 0" xyz="0 0 0"/>
      <geometry>
        <mesh filename="package://kurt_description/meshes/kurt_wheel_outdoor.stl"/>
      </geometry>
      <material name="blackish">
        <color rgba="0.1 0.1 0.1 1"/>
      </material>
    </visual>
    <collision>
      <origin rpy="0 0 0" xyz="0 0 0"/>
      <geometry>
        <mesh filename="package://kurt_description/meshes/kurt_wheel_outdoor.stl"/>
        <!-- <cylinder length="${wheel_width}" radius="${wheel_radius}" /> -->
      </geometry>
    </collision>
    <inertial>
      <mass value="0.15"/>
      <origin xyz="0 0 0"/>
      <inertia ixx="0.000177810" ixy="0.0" ixz="0.0" iyy="0.000332643" iyz="0.0" izz="0.000177810"/>
    </inertial>
  </link>
  <joint name="left_rear_wheel_joint" type="continuous">
    <origin rpy="0 0 0" xyz="-0.14 0.14 -0.107"/>
    <parent link="base_link"/>
    <child link="left_rear_wheel_link"/>
    <axis xyz="0 1 0"/>
  </joint>
  <gazebo reference="kurt_wheel_left_rear">
    <material value="Gazebo/Grey"/>
  </gazebo>
  <link name="right_front_wheel_link">
    <visual>
      <origin rpy="0 0 0" xyz="0 0 0"/>
      <geometry>
        <mesh filename="package://kurt_description/meshes/kurt_wheel_outdoor.stl"/>
      </geometry>
      <material name="blackish">
        <color rgba="0.1 0.1 0.1 1"/>
      </material>
    </visual>
    <collision>
      <origin rpy="0 0 0" xyz="0 0 0"/>
      <geometry>
        <mesh filename="package://kurt_description/meshes/kurt_wheel_outdoor.stl"/>
        <!-- <cylinder length="${wheel_width}" radius="${wheel_radius}" /> -->
      </geometry>
    </collision>
    <inertial>
      <mass value="0.15"/>
      <origin xyz="0 0 0"/>
      <inertia ixx="0.000177810" ixy="0.0" ixz="0.0" iyy="0.000332643" iyz="0.0" izz="0.000177810"/>
    </inertial>
  </link>
  <joint name="right_front_wheel_joint" type="continuous">
    <origin rpy="0 0 0" xyz="0.14 -0.14 -0.107"/>
    <parent link="base_link"/>
    <child link="right_front_wheel_link"/>
    <axis xyz="0 1 0"/>
  </joint>
  <gazebo reference="kurt_wheel_right_front">
    <material value="Gazebo/Grey"/>
  </gazebo>
  <link name="right_middle_wheel_link">
    <visual>
      <origin rpy="0 0 0" xyz="0 0 0"/>
      <geometry>
        <mesh filename="package://kurt_description/meshes/kurt_wheel_outdoor.stl"/>
      </geometry>
      <material name="blackish">
        <color rgba="0.1 0.1 0.1 1"/>
      </material>
    </visual>
    <collision>
      <origin rpy="0 0 0" xyz="0 0 0"/>
      <geometry>
        <mesh filename="package://kurt_description/meshes/kurt_wheel_outdoor.stl"/>
        <!-- <cylinder length="${wheel_width}" radius="${wheel_radius}" /> -->
      </geometry>
    </collision>
    <inertial>
      <mass value="0.15"/>
      <origin xyz="0 0 0"/>
      <inertia ixx="0.000177810" ixy="0.0" ixz="0.0" iyy="0.000332643" iyz="0.0" izz="0.000177810"/>
    </inertial>
  </link>
  <joint name="right_middle_wheel_joint" type="continuous">
    <origin rpy="0 0 0" xyz="0 -0.195 -0.107"/>
    <parent link="base_link"/>
    <child link="right_middle_wheel_link"/>
    <axis xyz="0 1 0"/>
  </joint>
  <gazebo reference="kurt_wheel_right_middle">
    <material value="Gazebo/Grey"/>
  </gazebo>
  <link name="right_rear_wheel_link">
    <visual>
      <origin rpy="0 0 0" xyz="0 0 0"/>
      <geometry>
        <mesh filename="package://kurt_description/meshes/kurt_wheel_outdoor.stl"/>
      </geometry>
      <material name="blackish">
        <color rgba="0.1 0.1 0.1 1"/>
      </material>
    </visual>
    <collision>
      <origin rpy="0 0 0" xyz="0 0 0"/>
      <geometry>
        <mesh filename="package://kurt_description/meshes/kurt_wheel_outdoor.stl"/>
        <!-- <cylinder length="${wheel_width}" radius="${wheel_radius}" /> -->
      </geometry>
    </collision>
    <inertial>
      <mass value="0.15"/>
      <origin xyz="0 0 0"/>
      <inertia ixx="0.000177810" ixy="0.0" ixz="0.0" iyy="0.000332643" iyz="0.0" izz="0.000177810"/>
    </inertial>
  </link>
  <joint name="right_rear_wheel_joint" type="continuous">
    <origin rpy="0 0 0" xyz="-0.14 -0.14 -0.107"/>
    <parent link="base_link"/>
    <child link="right_rear_wheel_link"/>
    <axis xyz="0 1 0"/>
  </joint>
  <gazebo reference="kurt_wheel_right_rear">
    <material value="Gazebo/Grey"/>
  </gazebo>
  <link name="base_footprint">
    <!-- this needs to have a fake inertial element, otherwise all children will be ignored by Gazebo -->
    <inertial>
      <mass value="0.0001"/>
      <origin xyz="0 0 0"/>
      <inertia ixx="0.0001" ixy="0.0" ixz="0.0" iyy="0.0001" iyz="0.0" izz="0.0001"/>
    </inertial>
  </link>
  <joint name="base_footprint_joint" type="fixed">
    <origin rpy="0 0 0" xyz="0 0 0.18944"/>
    <parent link="base_footprint"/>
    <child link="base_link"/>
  </joint>
  <link name="kurtana_rackplate_link">
    <visual>
      <origin rpy="0 0 0" xyz="0 0 0"/>
      <geometry>
        <box size="0.47 0.368 0.023"/>
      </geometry>
      <material name="grey">
        <color rgba="0.8 0.8 0.8 1"/>
      </material>
    </visual>
    <collision>
      <origin rpy="0 0 0" xyz="0 0 0"/>
      <geometry>
        <box size="0.47 0.368 0.023"/>
      </geometry>
    </collision>
    <inertial>
      <mass value="0.5"/>
      <origin xyz="0 0 0"/>
      <inertia ixx="0.00566470606745" ixy="0.0" ixz="0.0" iyy="0.00922620464285" iyz="0.0" izz="0.0148468273946"/>
    </inertial>
  </link>
  <joint name="kurtana_baseplate_joint" type="fixed">
    <parent link="kurtana_rackplate_link"/>
    <child link="kurtana_baseplate_link"/>
    <origin xyz="0 0 0.0695"/>
  </joint>
  <link name="kurtana_baseplate_link">
    <visual>
      <origin rpy="0 0 0" xyz="0 0 0"/>
      <geometry>
        <box size="0.47 0.368 0.006"/>
      </geometry>
      <material name="grey"/>
    </visual>
    <collision>
      <origin rpy="0 0 0" xyz="0 0 0"/>
      <geometry>
        <box size="0.47 0.368 0.006"/>
      </geometry>
    </collision>
    <inertial>
      <mass value="0.5"/>
      <origin xyz="0 0 0"/>
      <inertia ixx="0.005644164409" ixy="0.0" ixz="0.0" iyy="0.0092056629844" iyz="0.0" izz="0.0148468273946"/>
    </inertial>
  </link>
  <joint name="kurtana_pole_joint" type="fixed">
    <parent link="kurtana_baseplate_link"/>
    <child link="kurtana_pole_link"/>
    <origin xyz="-0.26 0 0.35"/>
  </joint>
  <link name="kurtana_pole_link">
    <visual>
      <origin rpy="0 0 0" xyz="0 0 0"/>
      <geometry>
        <cylinder length="0.7" radius="0.025"/>
      </geometry>
      <material name="grey"/>
    </visual>
    <collision>
      <origin rpy="0 0 0" xyz="0 0 0"/>
      <geometry>
        <cylinder length="0.7" radius="0.025"/>
      </geometry>
    </collision>
    <inertial>
      <mass value="3.0"/>
      <origin xyz="0 0 0"/>
      <inertia ixx="0.122968700812" ixy="0.0" ixz="0.0" iyy="0.122968700812" iyz="0.0" izz="0.0009375"/>
    </inertial>
  </link>
  <joint name="kurtana_stretch_joint" type="prismatic">
    <parent link="kurtana_pole_link"/>
    <child link="kurtana_innerpole_stretch_link"/>
    <origin rpy="0 0 0" xyz="0 0 0.1125"/>
    <limit effort="1000.0" lower="0" upper="0.515" velocity="0.5"/>
    <axis xyz="0 0 1"/>
  </joint>
  <link name="kurtana_innerpole_stretch_link">
    <visual>
      <origin rpy="0 0 0" xyz="0 0 0"/>
      <geometry>
        <cylinder length="0.555" radius="0.02"/>
      </geometry>
      <material name="grey"/>
    </visual>
    <collision>
      <origin rpy="0 0 0" xyz="0 0 0"/>
      <geometry>
        <cylinder length="0.555" radius="0.02"/>
      </geometry>
    </collision>
    <inertial>
      <mass value="2.0"/>
      <origin xyz="0 0 0"/>
      <inertia ixx="0.051537479385" ixy="0.0" ixz="0.0" iyy="0.051537479385" iyz="0.0" izz="0.0004"/>
    </inertial>
  </link>
  <joint name="kurtana_roll_joint" type="revolute">
    <parent link="kurtana_innerpole_stretch_link"/>
    <child link="kurtana_poletop_roll_link"/>
    <origin rpy="0 0 0" xyz="0 0 0.2575"/>
    <axis xyz="0 0 1"/>
    <limit effort="1000.0" lower="-1.57079632679" upper="1.57079632679" velocity="2.0"/>
  </joint>
  <link name="kurtana_poletop_roll_link">
    <visual>
      <origin rpy="0 0 0" xyz="0 0 0"/>
      <geometry>
        <cylinder length="0.04" radius="0.025"/>
      </geometry>
      <material name="grey"/>
    </visual>
    <collision>
      <origin rpy="0 0 0" xyz="0 0 0"/>
      <geometry>
        <cylinder length="0.04" radius="0.025"/>
      </geometry>
    </collision>
    <inertial>
      <mass value="0.1"/>
      <origin xyz="0 0 0"/>
      <inertia ixx="2.895832175e-05" ixy="0.0" ixz="0.0" iyy="2.895832175e-05" iyz="0.0" izz="3.125e-05"/>
    </inertial>
  </link>
  <joint name="kurtana_pitch_joint" type="revolute">
    <parent link="kurtana_poletop_roll_link"/>
    <child link="kurtana_pitchpole_link"/>
    <origin rpy="0 0 0" xyz="0 0 0"/>
    <axis xyz="0 1 0"/>
    <limit effort="1000.0" lower="-1.57079632679" upper="1.57079632679" velocity="2.0"/>
  </joint>
  <link name="kurtana_pitchpole_link">
    <visual>
      <origin rpy="-1.57079632679 0 0" xyz="0 0 0"/>
      <geometry>
        <cylinder length="0.23" radius="0.012"/>
      </geometry>
      <material name="grey"/>
    </visual>
    <collision>
      <origin rpy="-1.57079632679 0 0" xyz="0 0 0"/>
      <geometry>
        <cylinder length="0.23" radius="0.012"/>
      </geometry>
    </collision>
    <inertial>
      <mass value="0.05"/>
      <origin xyz="0 0 0"/>
      <inertia ixx="0.00022221657778" ixy="0.0" ixz="0.0" iyy="0.00022221657778" iyz="0.0" izz="3.6e-06"/>
    </inertial>
  </link>
  <transmission name="kurtana_stretch_trans" type="pr2_mechanism_model/SimpleTransmission">
    <actuator name="kurtana_stretch_motor"/>
    <joint name="kurtana_stretch_joint"/>
    <mechanicalReduction>1</mechanicalReduction>
    <motorTorqueConstant>1</motorTorqueConstant>
  </transmission>
  <transmission name="kurtana_roll_trans" type="pr2_mechanism_model/SimpleTransmission">
    <actuator name="kurtana_roll_motor"/>
    <joint name="kurtana_roll_joint"/>
    <mechanicalReduction>1</mechanicalReduction>
    <motorTorqueConstant>1</motorTorqueConstant>
  </transmission>
  <transmission name="kurtana_pitch_trans" type="pr2_mechanism_model/SimpleTransmission">
    <actuator name="kurtana_pitch_motor"/>
    <joint name="kurtana_pitch_joint"/>
    <mechanicalReduction>1</mechanicalReduction>
    <motorTorqueConstant>1</motorTorqueConstant>
  </transmission>
  <gazebo reference="kurtana_rackplate_link">
    <material value="PR2/Grey1"/>
  </gazebo>
  <gazebo reference="kurtana_baseplate_link">
    <material value="PR2/Grey1"/>
  </gazebo>
  <gazebo reference="kurtana_pole_link">
    <material value="PR2/Grey1"/>
  </gazebo>
  <gazebo reference="kurtana_innerpole_stretch_link">
    <material value="PR2/Grey1"/>
  </gazebo>
  <gazebo reference="kurtana_poletop_roll_link">
    <material value="PR2/Grey1"/>
  </gazebo>
  <gazebo reference="kurtana_pitchpole_link">
    <material value="PR2/Grey1"/>
  </gazebo>
  <link name="kinect_link">
    <visual>
      <origin rpy="0 0 0" xyz="0 0 0"/>
      <geometry>
        <mesh filename="package://pr2_description/meshes/sensors/kinect_v0/kinect.dae" scale="0.001 0.001 0.001"/>
      </geometry>
    </visual>
    <collision>
      <origin rpy="0 0 0" xyz="-0.0315 0 -0.017"/>
      <geometry>
        <box size="0.0730 0.2760 0.0720"/>
      </geometry>
    </collision>
    <inertial>
      <mass value="0.43"/>
      <origin xyz="0 0 0"/>
      <inertia ixx="0.00291539883384" ixy="0.0" ixz="0.0" iyy="0.000376715682647" iyz="0.0" izz="0.0029205946651"/>
    </inertial>
  </link>
  <joint name="kinect_depth_joint" type="fixed">
    <origin rpy="0 0 0" xyz="0 0.018 0"/>
    <parent link="kinect_link"/>
    <child link="kinect_depth_frame"/>
  </joint>
  <link name="kinect_depth_frame">
    <inertial>
      <mass value="0.000001"/>
      <origin xyz="0 0 0"/>
      <inertia ixx="0.0001" ixy="0.0" ixz="0.0" iyy="0.0001" iyz="0.0" izz="0.0001"/>
    </inertial>
  </link>
  <joint name="kinect_depth_optical_joint" type="fixed">
    <origin rpy="-1.57079632679 0 -1.57079632679" xyz="0 0 0"/>
    <parent link="kinect_depth_frame"/>
    <child link="kinect_depth_optical_frame"/>
  </joint>
  <link name="kinect_depth_optical_frame">
    <inertial>
      <mass value="0.000001"/>
      <origin xyz="0 0 0"/>
      <inertia ixx="0.0001" ixy="0.0" ixz="0.0" iyy="0.0001" iyz="0.0" izz="0.0001"/>
    </inertial>
  </link>
  <gazebo reference="kinect_depth_frame">
    <sensor name="kinect_depth_frame_ir_sensor" type="depth">
      <always_on>true</always_on>
      <update_rate>1.0</update_rate>
      <camera>
        <horizontal_fov>0.994837673637</horizontal_fov>
        <image>
          <format>L8</format>
          <width>640</width>
          <height>480</height>
        </image>
        <clip>
          <near>0.01</near>
          <far>5</far>
        </clip>
      </camera>
      <plugin filename="libgazebo_ros_openni_kinect.so" name="kinect_depth_frame_controller">
        <alwaysOn>true</alwaysOn>
        <updateRate>1.0</updateRate>
        <cameraName>kinect_ir</cameraName>
        <imageTopicName>/kinect/depth/image_raw</imageTopicName>
        <cameraInfoTopicName>/kinect/depth/camera_info</cameraInfoTopicName>
        <depthImageTopicName>/kinect/depth/image_raw</depthImageTopicName>
        <depthImageInfoTopicName>/kinect/depth/camera_info</depthImageInfoTopicName>
        <pointCloudTopicName>/kinect/depth/points</pointCloudTopicName>
        <frameName>kinect_depth_optical_frame</frameName>
        <pointCloudCutoff>0.5</pointCloudCutoff>
        <distortionK1>0.00000001</distortionK1>
        <distortionK2>0.00000001</distortionK2>
        <distortionK3>0.00000001</distortionK3>
        <distortionT1>0.00000001</distortionT1>
        <distortionT2>0.00000001</distortionT2>
      </plugin>
    </sensor>
    <material value="Gazebo/Red"/>
  </gazebo>
  <joint name="kinect_rgb_joint" type="fixed">
    <origin rpy="0 0 0" xyz="0 -0.005 0"/>
    <parent link="kinect_link"/>
    <child link="kinect_rgb_frame"/>
  </joint>
  <link name="kinect_rgb_frame">
    <inertial>
      <mass value="0.000001"/>
      <origin xyz="0 0 0"/>
      <inertia ixx="0.0001" ixy="0.0" ixz="0.0" iyy="0.0001" iyz="0.0" izz="0.0001"/>
    </inertial>
  </link>
  <joint name="kinect_rgb_optical_joint" type="fixed">
    <origin rpy="-1.57079632679 0 -1.57079632679" xyz="0 0 0"/>
    <parent link="kinect_rgb_frame"/>
    <child link="kinect_rgb_optical_frame"/>
  </joint>
  <link name="kinect_rgb_optical_frame">
    <inertial>
      <mass value="0.000001"/>
      <origin xyz="0 0 0"/>
      <inertia ixx="0.0001" ixy="0.0" ixz="0.0" iyy="0.0001" iyz="0.0" izz="0.0001"/>
    </inertial>
  </link>
  <gazebo reference="kinect_rgb_frame">
    <sensor name="kinect_rgb_sensor" type="depth">
      <always_on>true</always_on>
      <update_rate>1.0</update_rate>
      <camera>
        <horizontal_fov>0.994837673637</horizontal_fov>
        <image>
          <format>R8G8B8</format>
          <width>640</width>
          <height>480</height>
        </image>
        <clip>
          <near>0.01</near>
          <far>5</far>
        </clip>
      </camera>
      <plugin filename="libgazebo_ros_openni_kinect.so" name="kinect_rgb_frame_controller">
        <alwaysOn>true</alwaysOn>
        <updateRate>1.0</updateRate>
        <cameraName>kinect_rgb</cameraName>
        <imageTopicName>/kinect/rgb/image_raw</imageTopicName>
        <cameraInfoTopicName>/kinect/rgb/camera_info</cameraInfoTopicName>
        <pointCloudTopicName>/kinect/depth_registered/points</pointCloudTopicName>
        <frameName>kinect_rgb_optical_frame</frameName>
        <pointCloudCutoff>0.5</pointCloudCutoff>
        <distortionK1>0.00000001</distortionK1>
        <distortionK2>0.00000001</distortionK2>
        <distortionK3>0.00000001</distortionK3>
        <distortionT1>0.00000001</distortionT1>
        <distortionT2>0.00000001</distortionT2>
      </plugin>
    </sensor>
    <material value="Gazebo/Red"/>
  </gazebo>
  <joint name="kurtana_kinect_joint" type="fixed">
    <parent link="kurtana_pitchpole_link"/>
    <child link="kinect_link"/>
    <origin rpy="0 0 0" xyz="0.145 0 0.227"/>
  </joint>
  <link name="laser_mount_link">
    <inertial>
      <mass value="0.001"/>
      <origin xyz="0 0 0"/>
      <inertia ixx="0.000001" ixy="0.0" ixz="0.0" iyy="0.000001" iyz="0.0" izz="0.000001"/>
    </inertial>
  </link>
  <joint name="laser_joint" type="fixed">
    <parent link="laser_mount_link"/>
    <child link="laser"/>
    <origin rpy="0 0 0" xyz="0 0 0.05609"/>
  </joint>
  <link name="laser">
    <visual>
      <geometry>
        <mesh filename="package://sick_tim3xx/meshes/sick_tim3xx.stl"/>
      </geometry>
      <material name="blue">
        <color rgba="0 0 1 1"/>
      </material>
    </visual>
    <collision>
      <geometry>
        <mesh filename="package://sick_tim3xx/meshes/sick_tim3xx.stl"/>
      </geometry>
    </collision>
    <inertial>
      <mass value="0.15"/>
      <origin xyz="0 0 -0.026"/>
      <inertia ixx="0.00012499995" ixy="0.0" ixz="0.0" iyy="0.00012499995" iyz="0.0" izz="8.9999964e-05"/>
    </inertial>
  </link>
  <gazebo reference="laser">
    <material value="Gazebo/Blue"/>
    <sensor:ray name="laser">
      <rayCount>271</rayCount>
      <rangeCount>271</rangeCount>
      <laserCount>1</laserCount>
      <origin>0.0 0.0 0.0</origin>
      <displayRays>false</displayRays>
      <minAngle>-135</minAngle>
      <maxAngle>135</maxAngle>
      <minRange>0.05</minRange>
      <maxRange>4.0</maxRange>
      <resRange>0.01</resRange>
      <updateRate>15.0</updateRate>
      <controller:gazebo_ros_laser name="gazebo_ros_laser_controller" plugin="libgazebo_ros_laser.so">
        <gaussianNoise>0.005</gaussianNoise>
        <alwaysOn>true</alwaysOn>
        <updateRate>15.0</updateRate>
        <topicName>scan</topicName>
        <frameName>laser</frameName>
        <interface:laser name="gazebo_ros_laser_iface"/>
      </controller:gazebo_ros_laser>
    </sensor:ray>
  </gazebo>
  <joint name="kurtana_laser_joint" type="fixed">
    <parent link="kurtana_baseplate_link"/>
    <child link="laser_mount_link"/>
    <origin rpy="0 0 0" xyz="0.205 0 0.003"/>
  </joint>
  <link name="katana_internal_controlbox_link">
    <visual>
      <origin rpy="0 0 3.14159265359" xyz="0 0 0"/>
      <geometry>
        <mesh filename="package://katana_description/meshes/katana/katana_internal_controlbox.stl"/>
      </geometry>
      <material name="grey">
        <color rgba="0.8 0.8 0.8 1"/>
      </material>
    </visual>
    <collision>
      <origin rpy="0 0 3.14159265359" xyz="0 0 0"/>
      <geometry>
        <mesh filename="package://katana_description/meshes/katana/convex/katana_internal_controlbox_convex.stl"/>
      </geometry>
    </collision>
    <inertial>
      <mass value="4.47057045"/>
      <origin xyz="0.000024 -0.006508 0.030555"/>
      <inertia ixx="0.013760086" ixy="-0.000000539" ixz="-0.000000442" iyy="0.015251808" iyz="0.000361753" izz="0.023409309"/>
    </inertial>
  </link>
  <joint name="katana_base_joint" type="fixed">
    <parent link="katana_internal_controlbox_link"/>
    <child link="katana_base_link"/>
    <origin xyz="0 0 0.073"/>
  </joint>
  <gazebo reference="katana_internal_controlbox_link">
    <material value="Gazebo/Grey"/>
  </gazebo>
  <transmission name="katana_motor1_pan_trans" type="pr2_mechanism_model/SimpleTransmission">
    <actuator name="katana_motor1_pan_motor"/>
    <joint name="katana_motor1_pan_joint"/>
    <mechanicalReduction>1</mechanicalReduction>
    <motorTorqueConstant>1</motorTorqueConstant>
  </transmission>
  <transmission name="katana_motor2_lift_trans" type="pr2_mechanism_model/SimpleTransmission">
    <actuator name="katana_motor2_lift_motor"/>
    <joint name="katana_motor2_lift_joint"/>
    <mechanicalReduction>1</mechanicalReduction>
    <motorTorqueConstant>1</motorTorqueConstant>
  </transmission>
  <transmission name="katana_motor3_lift_trans" type="pr2_mechanism_model/SimpleTransmission">
    <actuator name="katana_motor3_lift_motor"/>
    <joint name="katana_motor3_lift_joint"/>
    <mechanicalReduction>1</mechanicalReduction>
    <motorTorqueConstant>1</motorTorqueConstant>
  </transmission>
  <transmission name="katana_motor4_lift_trans" type="pr2_mechanism_model/SimpleTransmission">
    <actuator name="katana_motor4_lift_motor"/>
    <joint name="katana_motor4_lift_joint"/>
    <mechanicalReduction>1</mechanicalReduction>
    <motorTorqueConstant>1</motorTorqueConstant>
  </transmission>
  <transmission name="katana_motor5_wrist_roll_trans" type="pr2_mechanism_model/SimpleTransmission">
    <actuator name="katana_motor5_wrist_roll_motor"/>
    <joint name="katana_motor5_wrist_roll_joint"/>
    <mechanicalReduction>1</mechanicalReduction>
    <motorTorqueConstant>1</motorTorqueConstant>
  </transmission>
  <transmission name="katana_r_finger_trans" type="pr2_mechanism_model/SimpleTransmission">
    <actuator name="katana_r_finger_motor"/>
    <joint name="katana_r_finger_joint"/>
    <mechanicalReduction>1</mechanicalReduction>
    <motorTorqueConstant>1</motorTorqueConstant>
  </transmission>
  <transmission name="katana_l_finger_trans" type="pr2_mechanism_model/SimpleTransmission">
    <actuator name="katana_l_finger_motor"/>
    <joint name="katana_l_finger_joint"/>
    <mechanicalReduction>1</mechanicalReduction>
    <motorTorqueConstant>1</motorTorqueConstant>
  </transmission>
  <gazebo>
    <!-- controller for the 5 arm joints -->
    <plugin filename="libgazebo_ros_controller_manager.so" name="gazebo_ros_controller_manager">
      <alwaysOn>true</alwaysOn>
      <updateRate>1000.0</updateRate>
      <interface:audio name="gazebo_ros_controller_manager_dummy_iface"/>
    </plugin>
    <!-- gripper controller -->
    <plugin filename="libgazebo_ros_katana_gripper.so" name="katana_gripper_controller">
      <alwaysOn>true</alwaysOn>
      <node_namespace>katana</node_namespace>
      <r_finger_joint>katana_r_finger_joint</r_finger_joint>
      <l_finger_joint>katana_l_finger_joint</l_finger_joint>
      <updateRate>1000.0</updateRate>
      <max_torque>0.5</max_torque>
    </plugin>
    <!-- a formal implementation of grasp hack in gazebo with fixed joint -->
    <gripper name="katana_gripper_grasp_hack">
      <grasp_check attach_steps="20" detach_steps="40" min_contact_count="2"/>
      <gripper_link>katana_r_finger_link</gripper_link>
      <gripper_link>katana_l_finger_link</gripper_link>
      <palm_link>katana_gripper_link</palm_link>
    </gripper>
  </gazebo>
  <gazebo reference="katana_base_link">
    <material value="Gazebo/Grey"/>
  </gazebo>
  <gazebo reference="katana_motor1_pan_link">
    <material value="Gazebo/Grey"/>
    <turnGravityOff>true</turnGravityOff>
  </gazebo>
  <gazebo reference="katana_motor2_lift_link">
    <material value="Gazebo/Grey"/>
    <turnGravityOff>true</turnGravityOff>
  </gazebo>
  <gazebo reference="katana_motor3_lift_link">
    <material value="Gazebo/Grey"/>
    <turnGravityOff>true</turnGravityOff>
  </gazebo>
  <gazebo reference="katana_motor4_lift_link">
    <material value="Gazebo/Grey"/>
    <turnGravityOff>true</turnGravityOff>
  </gazebo>
  <gazebo reference="katana_motor5_wrist_roll_link">
    <material value="Gazebo/Grey"/>
    <turnGravityOff>true</turnGravityOff>
  </gazebo>
  <gazebo reference="katana_gripper_link">
    <material value="Gazebo/Grey"/>
    <turnGravityOff>true</turnGravityOff>
  </gazebo>
  <gazebo reference="katana_r_finger_link">
    <material value="Gazebo/Grey"/>
    <turnGravityOff>true</turnGravityOff>
  </gazebo>
  <gazebo reference="katana_l_finger_link">
    <material value="Gazebo/Grey"/>
    <turnGravityOff>true</turnGravityOff>
  </gazebo>
  <gazebo reference="katana_motor1_pan_joint">
    <initial_joint_position>-3.022</initial_joint_position>
  </gazebo>
  <gazebo reference="katana_motor2_lift_joint">
    <initial_joint_position>2.163</initial_joint_position>
  </gazebo>
  <gazebo reference="katana_motor3_lift_joint">
    <initial_joint_position>-2.207</initial_joint_position>
  </gazebo>
  <gazebo reference="katana_motor4_lift_joint">
    <initial_joint_position>-2.026</initial_joint_position>
  </gazebo>
  <gazebo reference="katana_motor5_wrist_roll_joint">
    <initial_joint_position>-2.990</initial_joint_position>
  </gazebo>
  <gazebo reference="katana_r_finger_joint">
    <initial_joint_position>0.3</initial_joint_position>
  </gazebo>
  <gazebo reference="katana_l_finger_joint">
    <initial_joint_position>0.3</initial_joint_position>
  </gazebo>
  <link name="katana_base_link">
    <visual>
      <origin rpy="0 0 0" xyz="0 0 0"/>
      <geometry>
        <mesh filename="package://katana_description/meshes/katana/katana_base_link.stl"/>
      </geometry>
      <material name="grey">
        <color rgba="0.8 0.8 0.8 1"/>
      </material>
    </visual>
    <collision>
      <origin rpy="0 0 0" xyz="0 0 0"/>
      <geometry>
        <mesh filename="package://katana_description/meshes/katana/convex/katana_base_link_convex.stl"/>
      </geometry>
    </collision>
    <inertial>
      <mass value="1.4047990875"/>
      <origin xyz="-0.000327 0.000908 0.058457"/>
      <inertia ixx="0.003000703" ixy="0.000000864" ixz="-0.000011312" iyy="0.002974822" iyz="0.000036294" izz="0.001434739"/>
    </inertial>
  </link>
  <joint name="katana_motor1_pan_joint" type="revolute">
    <!-- Joint 1 in Katana Manual -->
    <parent link="katana_base_link"/>
    <child link="katana_motor1_pan_link"/>
    <origin rpy="0 0 0" xyz="0 0 0.2015"/>
    <axis xyz="0 0 1"/>
    <limit effort="1.5" lower="-3.025528" upper="2.891097" velocity="2.208932"/>
  </joint>
  <link name="katana_motor1_pan_link">
    <visual>
      <origin rpy="0 0 0" xyz="0 0 -0.2015"/>
      <geometry>
        <mesh filename="package://katana_description/meshes/katana/katana_motor1_pan_link.stl"/>
      </geometry>
      <material name="grey"/>
    </visual>
    <collision>
      <origin rpy="0 0 0" xyz="0 0 -0.2015"/>
      <geometry>
        <mesh filename="package://katana_description/meshes/katana/convex/katana_motor1_pan_link_convex.stl"/>
      </geometry>
    </collision>
    <inertial>
      <mass value="0.74793301875"/>
      <origin xyz="-0.000410 -0.001285 -0.016774"/>
      <inertia ixx="0.001737241" ixy="0.000000421" ixz="0.000000650" iyy="0.000998782" iyz="0.000016114" izz="0.001349170"/>
    </inertial>
  </link>
  <joint name="katana_motor2_lift_joint" type="revolute">
    <!-- Joint 2 in Katana Manual -->
    <parent link="katana_motor1_pan_link"/>
    <child link="katana_motor2_lift_link"/>
    <origin rpy="1.57079632679 0 0" xyz="0 0 0"/>
    <axis xyz="0 0 1"/>
    <limit effort="0.6" lower="-0.135228" upper="2.168572" velocity="1.190799"/>
  </joint>
  <link name="katana_motor2_lift_link">
    <visual>
      <origin rpy="-1.57079632679 0 0" xyz="0 0 0"/>
      <geometry>
        <mesh filename="package://katana_description/meshes/katana/katana_motor2_lift_link.stl"/>
      </geometry>
      <!-- <geometry>
          <cylinder length="${link2_length}" radius="0.02"/>
        </geometry>
        <origin rpy="0 ${-M_PI/2} 0" xyz="${link2_length/2} 0 0" /> -->
      <material name="grey"/>
    </visual>
    <collision>
      <origin rpy="-1.57079632679 0 0" xyz="0 0 0"/>
      <geometry>
        <mesh filename="package://katana_description/meshes/katana/convex/katana_motor2_lift_link_convex.stl"/>
      </geometry>
    </collision>
    <inertial>
      <mass value="0.80174941875"/>
      <origin xyz="0.092420 0.005283 0.000172"/>
      <inertia ixx="0.000478252" ixy="0.000081166" ixz="0.000003961" iyy="0.004314636" iyz="0.000000332" izz="0.004625444"/>
    </inertial>
  </link>
  <joint name="katana_motor3_lift_joint" type="revolute">
    <!-- Joint 3 in Katana Manual -->
    <parent link="katana_motor2_lift_link"/>
    <child link="katana_motor3_lift_link"/>
    <origin rpy="0 0 0" xyz="0.19 0 0"/>
    <axis xyz="0 0 1"/>
    <!-- unexplicably, the measured velocity limit of this motor is exactly half of what vel_enc2rad(180) says -->
    <limit effort="0.25" lower="-2.221804" upper="2.054223" velocity="1.190799"/>
  </joint>
  <link name="katana_motor3_lift_link">
    <visual>
      <origin rpy="-1.57079632679 0 0" xyz="0 0 0"/>
      <geometry>
        <mesh filename="package://katana_description/meshes/katana/katana_motor3_lift_link.stl"/>
      </geometry>
      <!--<geometry>
          <cylinder length="${link3_length}" radius="0.02"/>
        </geometry>
        <origin rpy="0 ${-M_PI/2} 0" xyz="${link3_length/2} 0 0" />-->
      <material name="grey"/>
    </visual>
    <collision>
      <origin rpy="-1.57079632679 0 0" xyz="0 0 0"/>
      <geometry>
        <mesh filename="package://katana_description/meshes/katana/convex/katana_motor3_lift_link_convex.stl"/>
      </geometry>
    </collision>
    <inertial>
      <mass value="0.79241664375"/>
      <origin xyz="0.058036 0.008963 -0.000187"/>
      <inertia ixx="0.001156089" ixy="0.000112877" ixz="-0.000004398" iyy="0.002305646" iyz="-0.000000036" izz="0.003128648"/>
    </inertial>
  </link>
  <joint name="katana_motor4_lift_joint" type="revolute">
    <!-- Joint 4 in Katana Manual -->
    <parent link="katana_motor3_lift_link"/>
    <child link="katana_motor4_lift_link"/>
    <origin rpy="3.14159265359 0 0" xyz="0.139 0 0"/>
    <axis xyz="0 0 1"/>
    <limit effort="0.1" lower="-2.033309" upper="1.876133" velocity="2.208932"/>
  </joint>
  <link name="katana_motor4_lift_link">
    <visual>
      <origin rpy="1.57079632679 0 0" xyz="0 0 0"/>
      <geometry>
        <mesh filename="package://katana_description/meshes/katana/katana_motor4_lift_link.stl"/>
      </geometry>
      <!-- <geometry>
          <cylinder length="${link4_length}" radius="0.02"/>
        </geometry>
        <origin rpy="0 ${-M_PI/2} 0" xyz="${link4_length/2} 0 0" /> -->
      <material name="grey"/>
    </visual>
    <collision>
      <origin rpy="1.57079632679 0 0" xyz="0 0 0"/>
      <geometry>
        <mesh filename="package://katana_description/meshes/katana/convex/katana_motor4_lift_link_convex.stl"/>
      </geometry>
    </collision>
    <inertial>
      <mass value="0.69149323125"/>
      <origin xyz="0.050401 0.005807 0.000000"/>
      <inertia ixx="0.000765999" ixy="0.000045260" ixz="-0.000001210" iyy="0.001504115" iyz="0.000000147" izz="0.001887277"/>
    </inertial>
  </link>
  <joint name="katana_motor5_wrist_roll_joint" type="revolute">
    <!-- Joint 5 in Katana Manual -->
    <parent link="katana_motor4_lift_link"/>
    <child link="katana_motor5_wrist_roll_link"/>
    <origin rpy="1.57079632679 0 -1.57079632679" xyz="0.1523 0 0"/>
    <axis xyz="0 0 1"/>
    <limit effort="0.01" lower="-2.993240" upper="2.870985" velocity="2.208932"/>
  </joint>
  <link name="katana_motor5_wrist_roll_link">
    <visual>
      <origin rpy="0 3.14159265359 0" xyz="0 0 0"/>
      <geometry>
        <mesh filename="package://katana_description/meshes/katana/katana_motor5_wrist_roll_link.stl"/>
      </geometry>
      <!--<geometry>
          <cylinder length="${link5_length}" radius="0.02"/>
        </geometry>
        <origin rpy="0 ${-M_PI/2} 0" xyz="${link5_length/2} 0 0" />-->
      <material name="grey"/>
    </visual>
    <collision>
      <origin rpy="0 3.14159265359 0" xyz="0 0 0"/>
      <geometry>
        <mesh filename="package://katana_description/meshes/katana/convex/katana_motor5_wrist_roll_link_convex.stl"/>
      </geometry>
    </collision>
    <inertial>
      <mass value="0.25622555625"/>
      <origin xyz="-0.003140899 0.000013920 0.001680144"/>
      <inertia ixx="0.000120481" ixy="0.000000015" ixz="-0.000001089" iyy="0.000132130" iyz="-0.000000124" izz="0.000093522"/>
    </inertial>
  </link>
  <joint name="katana_gripper_joint" type="fixed">
    <parent link="katana_motor5_wrist_roll_link"/>
    <child link="katana_gripper_link"/>
    <origin rpy="0 1.57079632679 0" xyz="0 0 -0.0323"/>
  </joint>
  <link name="katana_gripper_link">
    <visual>
      <origin rpy="0 3.14159265359 0" xyz="0 0 0"/>
      <geometry>
        <mesh filename="package://katana_description/meshes/katana/katana_gripper_link.stl"/>
      </geometry>
      <material name="grey"/>
    </visual>
    <collision>
      <origin rpy="0 3.14159265359 0" xyz="0 0 0"/>
      <geometry>
        <mesh filename="package://katana_description/meshes/katana/convex/katana_gripper_link_convex.stl"/>
      </geometry>
    </collision>
    <inertial>
      <mass value="0.0552136183596"/>
      <origin xyz="-0.014379 -0.000000 0.000006"/>
      <inertia ixx="0.000011468" ixy="0.000000000" ixz="0.000000007" iyy="0.000013830" iyz="0.000000000" izz="0.000011290"/>
    </inertial>
  </link>
  <joint name="katana_r_finger_joint" type="revolute">
    <parent link="katana_gripper_link"/>
    <child link="katana_r_finger_link"/>
    <origin rpy="0 0 0" xyz="0.034 0 0"/>
    <axis xyz="0 0 1"/>
    <limit effort="0.5" lower="-0.44" upper="0.30" velocity="0.718834"/>
  </joint>
  <link name="katana_r_finger_link">
    <visual>
      <origin rpy="0 3.14159265359 0" xyz="0 0 0"/>
      <geometry>
        <mesh filename="package://katana_description/meshes/katana/katana_gripper_r_finger.stl"/>
      </geometry>
      <material name="grey"/>
    </visual>
    <collision>
      <origin rpy="0 3.14159265359 0" xyz="0 0 0"/>
      <geometry>
        <mesh filename="package://katana_description/meshes/katana/convex/katana_gripper_r_finger_convex.stl"/>
      </geometry>
    </collision>
    <inertial>
      <mass value="0.0251722230462"/>
      <origin xyz="0.001784 0.025167 -.001603"/>
      <inertia ixx="0.000005990" ixy="0.000008473" ixz="0.000001448" iyy="0.000019757" iyz="-0.000000996" izz="0.000023588"/>
    </inertial>
  </link>
  <joint name="katana_l_finger_joint" type="revolute">
    <parent link="katana_gripper_link"/>
    <child link="katana_l_finger_link"/>
    <origin rpy="3.14159265359 0 0" xyz="0.034 0 0"/>
    <axis xyz="0 0 1"/>
    <limit effort="0.5" lower="-0.44" upper="0.30" velocity="0.718834"/>
  </joint>
  <link name="katana_l_finger_link">
    <visual>
      <origin rpy="0 3.14159265359 0" xyz="0 0 0"/>
      <geometry>
        <mesh filename="package://katana_description/meshes/katana/katana_gripper_l_finger.stl"/>
      </geometry>
      <material name="grey"/>
    </visual>
    <collision>
      <origin rpy="0 3.14159265359 0" xyz="0 0 0"/>
      <geometry>
        <mesh filename="package://katana_description/meshes/katana/convex/katana_gripper_l_finger_convex.stl"/>
      </geometry>
    </collision>
    <inertial>
      <mass value="0.0251722230462"/>
      <origin xyz="0.001784 0.025167 -.001603"/>
      <inertia ixx="0.000005990" ixy="0.000008473" ixz="0.000001448" iyy="0.000019757" iyz="-0.000000996" izz="0.000023588"/>
    </inertial>
  </link>
  <joint name="katana_gripper_tool_frame_joint" type="fixed">
    <parent link="katana_motor5_wrist_roll_link"/>
    <child link="katana_gripper_tool_frame"/>
    <origin rpy="0 1.57079632679 0" xyz="0 0 -0.1505"/>
  </joint>
  <link name="katana_gripper_tool_frame">
    <!-- This is the coordinate system of the tool (this is the position
         used in IK etc., relative to the base frame); there is no actual
         arm part attached to this link -->
  </link>
  <joint name="katana_base_frame_joint" type="fixed">
    <parent link="katana_base_link"/>
    <child link="katana_base_frame"/>
    <origin rpy="0 0 0" xyz="0 0 0.2015"/>
  </joint>
  <link name="katana_base_frame">
    <!-- This is the reference coordinate system of the arm (the KNI kinematics are specified
         in this frame); there is no actual arm part attached to this link -->
  </link>
  <param command="/opt/ros/groovy/stacks/xacro/xacro.py '/home/sp/groovy_rosbuild_workspace/katana_driver/katana_description/urdf/katana_300_6m180_with_controlbox.urdf.xacro'" name="robot_description"/>
  <joint name="kurtana_baseplate_controlbox_joint" type="fixed">
    <parent link="kurtana_baseplate_link"/>
    <child link="katana_internal_controlbox_link"/>
    <origin rpy="0 0 0" xyz="0.05 0 0.009"/>
  </joint>
  <joint name="top_base_joint" type="fixed">
    <parent link="base_link"/>
    <child link="kurtana_rackplate_link"/>
    <origin xyz="0 0.0 0.0115"/>
  </joint>
</robot>

