<?xml version="1.0" ?>
<!-- =================================================================================== -->
<!-- |    This document was autogenerated by xacro from /home/sp/groovy_rosbuild_workspace/kurt_driver/kurt_description/robots/kurtana.urdf.xacro | -->
<!-- |    EDITING THIS FILE BY HAND IS NOT RECOMMENDED                                 | -->
<!-- =================================================================================== -->
<robot name="kurtana" xmlns:controller="http://playerstage.sourceforge.net/gazebo/xmlschema/#controller" xmlns:interface="http://playerstage.sourceforge.net/gazebo/xmlschema/#interface" xmlns:sensor="http://playerstage.sourceforge.net/gazebo/xmlschema/#sensor" xmlns:xacro="http://ros.org/wiki/xacro">
  <!-- distance from base_link to top of cover surface -->
  <link name="base_link">
    <visual name="base_visual">
      <origin rpy="0 0 0" xyz="-0.045 0 0.148"/>
      <geometry name="pioneer_geom">
        <mesh filename="package://p2os_urdf/meshes/p3dx_meshes/chassis.stl"/>
      </geometry>
      <material name="ChassisRed">
        <color rgba="0.851 0.0 0.0 1.0"/>
      </material>
    </visual>
  </link>
  <gazebo reference="base_link">
    <material value="Gazebo/Red"/>
  </gazebo>
  <joint name="base_top_joint" type="fixed">
    <origin rpy="0 0 0" xyz="-0.045 0 0.234"/>
    <parent link="base_link"/>
    <child link="top_plate"/>
  </joint>
  <link name="top_plate">
    <visual>
      <inertial>
        <mass value="0.01"/>
        <origin xyz="0 0 0"/>
        <inertia ixx="1" ixy="0" ixz="0" iyy="1" iyz="0" izz="1"/>
      </inertial>
      <origin rpy="0 0 0" xyz="0 0 0"/>
      <geometry name="top_geom">
        <mesh filename="package://p2os_urdf/meshes/p3dx_meshes/top.stl"/>
      </geometry>
      <material name="TopBlack">
        <color rgba="0.038 0.038 0.038 1.0"/>
      </material>
    </visual>
  </link>
  <gazebo reference="top_plate">
    <material value="Gazebo/Black"/>
  </gazebo>
  <joint name="base_swivel_joint" type="continuous">
    <origin rpy="0 0 0" xyz="-0.185 0 0.055"/>
    <anchor xyz="0 0 0"/>
    <limit effort="100" k_velocity="0" velocity="100"/>
    <joint_properties damping="0.0" friction="0.0"/>
    <parent link="base_link"/>
    <child link="swivel"/>
  </joint>
  <link name="swivel">
    <inertial>
      <mass value="0.1"/>
      <origin xyz="0 0 0"/>
      <inertia ixx="0.01" ixy="0" ixz="0" iyy="0.01" iyz="0" izz="0.01"/>
    </inertial>
    <visual name="base_visual">
      <origin rpy="0 0 0" xyz="0 0 0"/>
      <geometry name="pioneer_geom">
        <mesh filename="package://p2os_urdf/meshes/p3dx_meshes/swivel.stl"/>
      </geometry>
      <material name="swivel">
        <color rgba="0.5 0.5 0.5 1"/>
      </material>
    </visual>
    <collision>
      <origin rpy="0 0 0" xyz="0 0 0"/>
      <geometry>
        <box size="0 0 0"/>
      </geometry>
    </collision>
  </link>
  <gazebo reference="swivel">
    <material value="Gazebo/Grey"/>
  </gazebo>
  <link name="center_hubcap">
    <inertial>
      <mass value="0.01"/>
      <origin xyz="0 0 0"/>
      <inertia ixx="0.012411765597" ixy="-0.000711733678" ixz="0.00050272983" iyy="0.015218160428" iyz="-0.000004273467" izz="0.011763977943"/>
    </inertial>
    <visual name="base_visual">
      <origin rpy="0 0 0" xyz="0 0 0"/>
      <geometry name="pioneer_geom">
        <mesh filename="package://p2os_urdf/meshes/p3dx_meshes/center_hubcap.stl"/>
      </geometry>
      <material name="swivel">
        <color rgba="0.5 0.5 0.5 1"/>
      </material>
    </visual>
    <collision>
      <origin rpy="0 0 0" xyz="0 0 0"/>
      <geometry>
        <box size="0 0 0"/>
      </geometry>
    </collision>
  </link>
  <gazebo reference="center_hubcap">
    <material value="Gazebo/Grey"/>
  </gazebo>
  <joint name="swivel_hubcap_joint" type="continuous">
    <origin rpy="0 0 0" xyz="-0.026 0 -0.016"/>
    <axis xyz="0 1 0"/>
    <anchor xyz="0 0 0"/>
    <limit effort="100" k_velocity="0" velocity="100"/>
    <joint_properties damping="0.0" friction="0.0"/>
    <parent link="swivel"/>
    <child link="center_wheel"/>
  </joint>
  <link name="center_wheel">
    <inertial>
      <mass value="0.1"/>
      <origin xyz="0 0 0"/>
      <inertia ixx="0.012411765597" ixy="-0.000711733678" ixz="0.00050272983" iyy="0.015218160428" iyz="-0.000004273467" izz="0.011763977943"/>
    </inertial>
    <visual name="base_visual">
      <origin rpy="0 0 0" xyz="0 0 0"/>
      <geometry name="pioneer_geom">
        <mesh filename="package://p2os_urdf/meshes/p3dx_meshes/center_wheel.stl"/>
      </geometry>
      <material name="WheelBlack">
        <color rgba="0.117 0.117 0.117 1"/>
      </material>
    </visual>
    <collision>
      <origin rpy="-1.57079635 0 0" xyz="0 0 0"/>
      <geometry>
        <!--<mesh filename="package://p2os_urdf/meshes/p3dx_meshes/center_wheel.stl"/>-->
        <cylinder length="0.01" radius="0.0375"/>
      </geometry>
    </collision>
  </link>
  <joint name="center_wheel_joint" type="fixed">
    <origin rpy="0 0 0" xyz="-0.0035 0 -0.001"/>
    <parent link="center_wheel"/>
    <child link="center_hubcap"/>
  </joint>
  <link name="left_hub">
    <visual>
      <origin rpy="0 0 0" xyz="0 0 0"/>
      <geometry>
        <mesh filename="package://p2os_urdf/meshes/p3dx_meshes/left_hubcap.stl"/>
      </geometry>
      <material name="HubcapYellow">
        <color rgba="1.0 0.811 0.151 1.0"/>
      </material>
    </visual>
  </link>
  <joint name="left_hub_joint" type="fixed">
    <origin rpy="0 0 0" xyz="0 0.15 0.08"/>
    <parent link="base_link"/>
    <child link="left_hub"/>
    <axis xyz="0 1 0"/>
  </joint>
  <link name="left_wheel_joint">
    <visual>
      <origin rpy="0 0 0" xyz="0 0 0"/>
      <geometry>
        <mesh filename="package://p2os_urdf/meshes/p3dx_meshes/left_wheel.stl"/>
      </geometry>
      <material name="WheelBlack">
        <color rgba="0.117 0.117 0.117 1"/>
      </material>
    </visual>
  </link>
  <joint name="left_wheel_joint" type="fixed">
    <origin rpy="0 0 0" xyz="0 0 0"/>
    <parent link="left_hub"/>
    <child link="left_wheel_joint"/>
  </joint>
  <link name="right_hub">
    <visual>
      <origin rpy="0 0 0" xyz="0 0 0"/>
      <geometry>
        <mesh filename="package://p2os_urdf/meshes/p3dx_meshes/right_hubcap.stl"/>
      </geometry>
      <material name="HubcapYellow">
        <color rgba="1.0 0.811 0.151 1.0"/>
      </material>
    </visual>
  </link>
  <joint name="right_hub_joint" type="fixed">
    <origin rpy="0 0 0" xyz="0 -0.15 0.08"/>
    <parent link="base_link"/>
    <child link="right_hub"/>
    <axis xyz="0 1 0"/>
  </joint>
  <link name="right_wheel_joint">
    <visual>
      <origin rpy="0 0 0" xyz="0 0 0"/>
      <geometry>
        <mesh filename="package://p2os_urdf/meshes/p3dx_meshes/right_wheel.stl"/>
      </geometry>
      <material name="WheelBlack">
        <color rgba="0.117 0.117 0.117 1"/>
      </material>
    </visual>
  </link>
  <joint name="right_wheel_joint" type="fixed">
    <origin rpy="0 0 0" xyz="0 0 0"/>
    <parent link="right_hub"/>
    <child link="right_wheel_joint"/>
  </joint>
  <link name="front_sonar">
    <inertial>
      <mass value="0.0001"/>
      <origin xyz="0 0 0"/>
      <inertia ixx="1" ixy="0" ixz="0" iyy="1" iyz="0" izz="1"/>
    </inertial>
    <visual name="base_visual">
      <origin rpy="0 0 0" xyz="0 0 0"/>
      <geometry name="pioneer_geom">
        <mesh filename="package://p2os_urdf/meshes/p3dx_meshes/front_sonar.stl"/>
      </geometry>
      <material name="SonarYellow">
        <color rgba="0.715 0.583 0.210 1.0"/>
      </material>
    </visual>
    <collision>
      <origin rpy="0 0 0" xyz="0 0 0"/>
      <geometry>
        <box size="0 0 0"/>
      </geometry>
    </collision>
  </link>
  <gazebo reference="front_sonar">
    <material value="Gazebo/Yellow"/>
  </gazebo>
  <joint name="base_front_joint" type="fixed">
    <origin rpy="0 0 0" xyz="-0.198 0 0.208"/>
    <parent link="base_link"/>
    <child link="front_sonar"/>
  </joint>
  <link name="back_sonar">
    <inertial>
      <mass value="0.0001"/>
      <origin xyz="0 0 0"/>
      <inertia ixx="1" ixy="0" ixz="0" iyy="1" iyz="0" izz="1"/>
    </inertial>
    <visual name="back_sonar_vis">
      <origin rpy="0 0 0" xyz="0 0 0"/>
      <geometry name="pioneer_geom">
        <mesh filename="package://p2os_urdf/meshes/p3dx_meshes/back_sonar.stl"/>
      </geometry>
      <material name="SonarYellow">
        <color rgba="0.715 0.583 0.210 1.0"/>
      </material>
    </visual>
    <collision>
      <origin rpy="0 0 0" xyz="0 0 0"/>
      <geometry>
        <box size="0 0 0"/>
      </geometry>
    </collision>
  </link>
  <gazebo reference="back_sonar">
    <material value="Gazebo/Yellow"/>
  </gazebo>
  <joint name="base_back_joint" type="fixed">
    <origin rpy="0 0 0" xyz="0.109 0 0.209"/>
    <parent link="base_link"/>
    <child link="back_sonar"/>
  </joint>
  <gazebo>
    <controller:diffdrive_plugin name="differential_drive_controller" plugin="libdiffdrive_plugin.so">
      <alwaysOn>true</alwaysOn>
      <update>100</update>
      <updateRate>100.0</updateRate>
      <leftJoint>base_right_wheel_joint</leftJoint>
      <rightJoint>base_left_wheel_joint</rightJoint>
      <wheelSeparation>0.39</wheelSeparation>
      <wheelDiameter>0.15</wheelDiameter>
      <torque>5</torque>
      <interface:position name="position_iface_0"/>
      <robotNamespace>/</robotNamespace>
      <topicName>cmd_vel</topicName>
    </controller:diffdrive_plugin>
    <controller:gazebo_ros_p3d name="p3d_base_controller" plugin="libgazebo_ros_p3d.so">
      <alwaysOn>true</alwaysOn>
      <updateRate>100.0</updateRate>
      <bodyName>base_link</bodyName>
      <topicName>base_pose_ground_truth</topicName>
      <gaussianNoise>0.01</gaussianNoise>
      <frameName>map</frameName>
      <xyzOffsets>0 0 0</xyzOffsets>
      <!-- initialize odometry for fake localization-->
      <rpyOffsets>0 0 0</rpyOffsets>
      <interface:position name="p3d_base_position"/>
    </controller:gazebo_ros_p3d>
    <controller:gazebo_ros_controller_manager name="gazebo_ros_controller_manager" plugin="libgazebo_ros_controller_manager.so">
      <alwaysOn>true</alwaysOn>
      <updateRate>1000.0</updateRate>
      <interface:audio name="gazebo_ros_controller_manager_dummy_iface"/>
    </controller:gazebo_ros_controller_manager>
  </gazebo>
  <link name="kurtana_baseplate_link">
    <visual>
      <origin rpy="0 0 0" xyz="0 0 0"/>
      <geometry>
        <box size="0.47 0.368 0.006"/>
      </geometry>
      <material name="grey"/>
    </visual>
    <collision>
      <origin rpy="0 0 0" xyz="0 0 0"/>
      <geometry>
        <box size="0.47 0.368 0.006"/>
      </geometry>
    </collision>
    <inertial>
      <mass value="0.5"/>
      <origin xyz="0 0 0"/>
      <inertia ixx="0.005644164409" ixy="0.0" ixz="0.0" iyy="0.0092056629844" iyz="0.0" izz="0.0148468273946"/>
    </inertial>
  </link>
  <joint name="katana_baseplate_joint" type="fixed">
    <parent link="kurtana_baseplate_link"/>
    <child link="katana_baseplate_link"/>
    <origin xyz="0.05 0 0.009"/>
  </joint>
  <link name="katana_baseplate_link">
    <visual>
      <origin rpy="0 0 0" xyz="0 0 0"/>
      <geometry>
        <box size="0.156 0.156 0.012"/>
      </geometry>
      <material name="grey"/>
    </visual>
    <collision>
      <origin rpy="0 0 0" xyz="0 0 0"/>
      <geometry>
        <box size="0.156 0.156 0.012"/>
      </geometry>
    </collision>
    <inertial>
      <mass value="0.4"/>
      <origin xyz="0 0 0"/>
      <inertia ixx="0.0008159996736" ixy="0.0" ixz="0.0" iyy="0.0008159996736" iyz="0.0" izz="0.00162239935104"/>
    </inertial>
  </link>
  <joint name="kurtana_pole_joint" type="fixed">
    <parent link="kurtana_baseplate_link"/>
    <child link="kurtana_pole_link"/>
    <origin xyz="-0.18 0 0.35"/>
  </joint>
  <link name="kurtana_pole_link">
    <visual>
      <origin rpy="0 0 0" xyz="0 0 0"/>
      <geometry>
        <box size="0.03 0.03 0.7"/>
      </geometry>
      <material name="grey"/>
    </visual>
    <collision>
      <origin rpy="0 0 0" xyz="0 0 0"/>
      <geometry>
        <box size="0.03 0.03 0.7"/>
      </geometry>
    </collision>
    <inertial>
      <mass value="3.0"/>
      <origin xyz="0 0 0"/>
      <inertia ixx="0.12272495091" ixy="0.0" ixz="0.0" iyy="0.12272495091" iyz="0.0" izz="0.00044999982"/>
    </inertial>
  </link>
  <joint name="kurtana_microphone_joint" type="fixed">
    <parent link="kurtana_pole_link"/>
    <child link="kurtana_microphone_link"/>
    <origin xyz="0.06 -0.055 0.385"/>
  </joint>
  <link name="kurtana_microphone_link">
    <visual>
      <origin rpy="0 1.57079632679 0" xyz="0 0 0"/>
      <geometry>
        <cylinder length="0.24" radius="0.025"/>
      </geometry>
      <material name="black"/>
    </visual>
    <collision>
      <origin rpy="0 1.57079632679 0" xyz="0 0 0"/>
      <geometry>
        <cylinder length="0.24" radius="0.025"/>
      </geometry>
    </collision>
    <inertial>
      <mass value="0.3"/>
      <origin xyz="0 0 0"/>
      <inertia ixx="0.00148687440525" ixy="0.0" ixz="0.0" iyy="0.00148687440525" iyz="0.0" izz="9.375e-05"/>
    </inertial>
  </link>
  <joint name="kurtana_horizontal_square_bar_joint" type="fixed">
    <parent link="kurtana_pole_link"/>
    <child link="kurtana_horizontal_square_bar_link"/>
    <origin xyz="0.0715 0 0.335"/>
  </joint>
  <link name="kurtana_horizontal_square_bar_link">
    <visual>
      <origin rpy="0 0 0" xyz="0 0 0"/>
      <geometry>
        <box size="0.113 0.03 0.03"/>
      </geometry>
      <material name="grey"/>
    </visual>
    <collision>
      <origin rpy="0 0 0" xyz="0 0 0"/>
      <geometry>
        <box size="0.113 0.03 0.03"/>
      </geometry>
    </collision>
    <inertial>
      <mass value="0.1"/>
      <origin xyz="0 0 0"/>
      <inertia ixx="1.4999994e-05" ixy="0.0" ixz="0.0" iyy="0.00011390828777" iyz="0.0" izz="0.00011390828777"/>
    </inertial>
  </link>
  <joint name="kurtana_vertical_square_bar_joint" type="fixed">
    <parent link="kurtana_horizontal_square_bar_link"/>
    <child link="kurtana_vertical_square_bar_link"/>
    <origin xyz="0.0415 0 0.05875"/>
  </joint>
  <link name="kurtana_vertical_square_bar_link">
    <visual>
      <origin rpy="0 0 0" xyz="0 0 0"/>
      <geometry>
        <box size="0.03 0.03 0.0875"/>
      </geometry>
      <material name="grey"/>
    </visual>
    <collision>
      <origin rpy="0 0 0" xyz="0 0 0"/>
      <geometry>
        <box size="0.03 0.03 0.0875"/>
      </geometry>
    </collision>
    <inertial>
      <mass value="0.1"/>
      <origin xyz="0 0 0"/>
      <inertia ixx="7.13020548125e-05" ixy="0.0" ixz="0.0" iyy="7.13020548125e-05" iyz="0.0" izz="1.4999994e-05"/>
    </inertial>
  </link>
  <joint name="kurtana_roll_servo_joint" type="fixed">
    <parent link="kurtana_vertical_square_bar_link"/>
    <child link="kurtana_roll_servo_link"/>
    <origin xyz="0.049 0 0.01875"/>
  </joint>
  <link name="kurtana_roll_servo_link">
    <visual>
      <origin rpy="0 0 0" xyz="0 0 0"/>
      <geometry>
        <box size="0.068 0.032 0.05"/>
      </geometry>
      <material name="grey"/>
    </visual>
    <collision>
      <origin rpy="0 0 0" xyz="0 0 0"/>
      <geometry>
        <box size="0.068 0.032 0.05"/>
      </geometry>
    </collision>
    <inertial>
      <mass value="0.15"/>
      <origin xyz="0 0 0"/>
      <inertia ixx="4.404998238e-05" ixy="0.0" ixz="0.0" iyy="8.904996438e-05" iyz="0.0" izz="7.059997176e-05"/>
    </inertial>
  </link>
  <joint name="kurtana_roll_joint" type="revolute">
    <parent link="kurtana_roll_servo_link"/>
    <child link="kurtana_pitch_servo_link"/>
    <origin xyz="0.008 0 0.059"/>
    <axis xyz="0 0 1"/>
    <limit effort="1000.0" lower="-0.5" upper="0.5" velocity="2.0"/>
  </joint>
  <link name="kurtana_pitch_servo_link">
    <visual>
      <origin rpy="0 0 0" xyz="0 0 0"/>
      <geometry>
        <box size="0.032 0.05 0.068"/>
      </geometry>
      <material name="grey"/>
    </visual>
    <collision>
      <origin rpy="0 0 0" xyz="0 0 0"/>
      <geometry>
        <box size="0.032 0.05 0.068"/>
      </geometry>
    </collision>
    <inertial>
      <mass value="0.15"/>
      <origin xyz="0 0 0"/>
      <inertia ixx="8.904996438e-05" ixy="0.0" ixz="0.0" iyy="7.059997176e-05" iyz="0.0" izz="4.404998238e-05"/>
    </inertial>
  </link>
  <joint name="kurtana_pitch_joint" type="revolute">
    <parent link="kurtana_pitch_servo_link"/>
    <child link="kurtana_pitch_servo_movable_part_link"/>
    <origin rpy="0 0.045 0" xyz="0 0 0.008"/>
    <axis xyz="0 1 0"/>
    <limit effort="1000.0" lower="0.8" upper="1.2" velocity="2.0"/>
  </joint>
  <link name="kurtana_pitch_servo_movable_part_link">
    <visual>
      <origin rpy="0 0 0" xyz="0 0 0"/>
      <geometry>
        <box size="0.032 0.05 0.035"/>
      </geometry>
      <material name="grey"/>
    </visual>
    <collision>
      <origin rpy="0 0 0" xyz="0 0 0"/>
      <geometry>
        <box size="0.032 0.05 0.035"/>
      </geometry>
    </collision>
    <inertial>
      <mass value="0.15"/>
      <origin xyz="0 0 0"/>
      <inertia ixx="4.6562481375e-05" ixy="0.0" ixz="0.0" iyy="2.8112488755e-05" iyz="0.0" izz="4.404998238e-05"/>
    </inertial>
  </link>
  <joint name="kurtana_kinect_mounting_plate_joint" type="fixed">
    <parent link="kurtana_pitch_servo_movable_part_link"/>
    <child link="kurtana_kinect_mounting_plate_link"/>
    <origin rpy="0 0 0" xyz="0 0 0.021"/>
  </joint>
  <link name="kurtana_kinect_mounting_plate_link">
    <visual>
      <origin rpy="0 0 0" xyz="0 0 0"/>
      <geometry>
        <box size="0.045 0.17 0.007"/>
      </geometry>
      <material name="grey"/>
    </visual>
    <collision>
      <origin rpy="0 0 0" xyz="0 0 0"/>
      <geometry>
        <box size="0.045 0.17 0.007"/>
      </geometry>
    </collision>
    <inertial>
      <mass value="0.05"/>
      <origin xyz="0 0 0"/>
      <inertia ixx="0.000120620785085" ixy="0.0" ixz="0.0" iyy="8.64166321e-06" iyz="0.0" izz="0.000128854115125"/>
    </inertial>
  </link>
  <transmission name="kurtana_stretch_trans" type="pr2_mechanism_model/SimpleTransmission">
    <actuator name="kurtana_stretch_motor"/>
    <joint name="kurtana_stretch_joint"/>
    <mechanicalReduction>1</mechanicalReduction>
    <motorTorqueConstant>1</motorTorqueConstant>
  </transmission>
  <transmission name="kurtana_roll_trans" type="pr2_mechanism_model/SimpleTransmission">
    <actuator name="kurtana_roll_motor"/>
    <joint name="kurtana_roll_joint"/>
    <mechanicalReduction>1</mechanicalReduction>
    <motorTorqueConstant>1</motorTorqueConstant>
  </transmission>
  <transmission name="kurtana_pitch_trans" type="pr2_mechanism_model/SimpleTransmission">
    <actuator name="kurtana_pitch_motor"/>
    <joint name="kurtana_pitch_joint"/>
    <mechanicalReduction>1</mechanicalReduction>
    <motorTorqueConstant>1</motorTorqueConstant>
  </transmission>
  <gazebo reference="kurtana_rackplate_link">
    <material value="PR2/Grey"/>
  </gazebo>
  <gazebo reference="kurtana_baseplate_link">
    <material value="PR2/Grey"/>
  </gazebo>
  <gazebo reference="kurtana_pole_link">
    <material value="PR2/Grey"/>
  </gazebo>
  <gazebo reference="kurtana_innerpole_stretch_link">
    <material value="PR2/Grey"/>
  </gazebo>
  <gazebo reference="kurtana_poletop_roll_link">
    <material value="PR2/Grey"/>
  </gazebo>
  <gazebo reference="kurtana_pitchpole_link">
    <material value="PR2/Grey"/>
  </gazebo>
  <link name="kinect_link">
    <visual>
      <origin rpy="0 0 0" xyz="0 0 0"/>
      <geometry>
        <mesh filename="package://pr2_description/meshes/sensors/kinect_v0/kinect.dae" scale="0.001 0.001 0.001"/>
      </geometry>
    </visual>
    <collision>
      <origin rpy="0 0 0" xyz="-0.0315 0 -0.017"/>
      <geometry>
        <box size="0.0730 0.2760 0.0720"/>
      </geometry>
    </collision>
    <inertial>
      <mass value="0.43"/>
      <origin xyz="0 0 0"/>
      <inertia ixx="0.00291539883384" ixy="0.0" ixz="0.0" iyy="0.000376715682647" iyz="0.0" izz="0.0029205946651"/>
    </inertial>
  </link>
  <joint name="kinect_depth_joint" type="fixed">
    <origin rpy="0 0 0" xyz="0 0.018 0"/>
    <parent link="kinect_link"/>
    <child link="kinect_depth_frame"/>
  </joint>
  <link name="kinect_depth_frame">
    <inertial>
      <mass value="0.000001"/>
      <origin xyz="0 0 0"/>
      <inertia ixx="0.0001" ixy="0.0" ixz="0.0" iyy="0.0001" iyz="0.0" izz="0.0001"/>
    </inertial>
  </link>
  <joint name="kinect_depth_optical_joint" type="fixed">
    <origin rpy="-1.57079632679 0 -1.57079632679" xyz="0 0 0"/>
    <parent link="kinect_depth_frame"/>
    <child link="kinect_depth_optical_frame"/>
  </joint>
  <link name="kinect_depth_optical_frame">
    <inertial>
      <mass value="0.000001"/>
      <origin xyz="0 0 0"/>
      <inertia ixx="0.0001" ixy="0.0" ixz="0.0" iyy="0.0001" iyz="0.0" izz="0.0001"/>
    </inertial>
  </link>
  <gazebo reference="kinect_depth_frame">
    <sensor name="kinect_depth_frame_ir_sensor" type="depth">
      <always_on>true</always_on>
      <update_rate>1.0</update_rate>
      <camera>
        <horizontal_fov>0.994837673637</horizontal_fov>
        <image>
          <format>L8</format>
          <width>640</width>
          <height>480</height>
        </image>
        <clip>
          <near>0.01</near>
          <far>5</far>
        </clip>
      </camera>
      <plugin filename="libgazebo_ros_openni_kinect.so" name="kinect_depth_frame_controller">
        <alwaysOn>true</alwaysOn>
        <updateRate>1.0</updateRate>
        <cameraName>kinect_ir</cameraName>
        <imageTopicName>/kinect/depth/image_raw</imageTopicName>
        <cameraInfoTopicName>/kinect/depth/camera_info</cameraInfoTopicName>
        <depthImageTopicName>/kinect/depth/image_raw</depthImageTopicName>
        <depthImageInfoTopicName>/kinect/depth/camera_info</depthImageInfoTopicName>
        <pointCloudTopicName>/kinect/depth/points</pointCloudTopicName>
        <frameName>kinect_depth_optical_frame</frameName>
        <pointCloudCutoff>0.5</pointCloudCutoff>
        <distortionK1>0.00000001</distortionK1>
        <distortionK2>0.00000001</distortionK2>
        <distortionK3>0.00000001</distortionK3>
        <distortionT1>0.00000001</distortionT1>
        <distortionT2>0.00000001</distortionT2>
      </plugin>
    </sensor>
    <material value="Gazebo/Red"/>
  </gazebo>
  <joint name="kinect_rgb_joint" type="fixed">
    <origin rpy="0 0 0" xyz="0 -0.005 0"/>
    <parent link="kinect_link"/>
    <child link="kinect_rgb_frame"/>
  </joint>
  <link name="kinect_rgb_frame">
    <inertial>
      <mass value="0.000001"/>
      <origin xyz="0 0 0"/>
      <inertia ixx="0.0001" ixy="0.0" ixz="0.0" iyy="0.0001" iyz="0.0" izz="0.0001"/>
    </inertial>
  </link>
  <joint name="kinect_rgb_optical_joint" type="fixed">
    <origin rpy="-1.57079632679 0 -1.57079632679" xyz="0 0 0"/>
    <parent link="kinect_rgb_frame"/>
    <child link="kinect_rgb_optical_frame"/>
  </joint>
  <link name="kinect_rgb_optical_frame">
    <inertial>
      <mass value="0.000001"/>
      <origin xyz="0 0 0"/>
      <inertia ixx="0.0001" ixy="0.0" ixz="0.0" iyy="0.0001" iyz="0.0" izz="0.0001"/>
    </inertial>
  </link>
  <gazebo reference="kinect_rgb_frame">
    <sensor name="kinect_rgb_sensor" type="depth">
      <always_on>true</always_on>
      <update_rate>1.0</update_rate>
      <camera>
        <horizontal_fov>0.994837673637</horizontal_fov>
        <image>
          <format>R8G8B8</format>
          <width>640</width>
          <height>480</height>
        </image>
        <clip>
          <near>0.01</near>
          <far>5</far>
        </clip>
      </camera>
      <plugin filename="libgazebo_ros_openni_kinect.so" name="kinect_rgb_frame_controller">
        <alwaysOn>true</alwaysOn>
        <updateRate>1.0</updateRate>
        <cameraName>kinect_rgb</cameraName>
        <imageTopicName>/kinect/rgb/image_raw</imageTopicName>
        <cameraInfoTopicName>/kinect/rgb/camera_info</cameraInfoTopicName>
        <pointCloudTopicName>/kinect/depth_registered/points</pointCloudTopicName>
        <frameName>kinect_rgb_optical_frame</frameName>
        <pointCloudCutoff>0.5</pointCloudCutoff>
        <distortionK1>0.00000001</distortionK1>
        <distortionK2>0.00000001</distortionK2>
        <distortionK3>0.00000001</distortionK3>
        <distortionT1>0.00000001</distortionT1>
        <distortionT2>0.00000001</distortionT2>
      </plugin>
    </sensor>
    <material value="Gazebo/Red"/>
  </gazebo>
  <joint name="kurtana_kinect_joint" type="fixed">
    <parent link="kurtana_kinect_mounting_plate_link"/>
    <child link="kinect_link"/>
    <origin rpy="0 0 0" xyz="0.03 0.0 0.018"/>
  </joint>
  <transmission name="katana_motor1_pan_trans" type="pr2_mechanism_model/SimpleTransmission">
    <actuator name="katana_motor1_pan_motor"/>
    <joint name="katana_motor1_pan_joint"/>
    <mechanicalReduction>1</mechanicalReduction>
    <motorTorqueConstant>1</motorTorqueConstant>
  </transmission>
  <transmission name="katana_motor2_lift_trans" type="pr2_mechanism_model/SimpleTransmission">
    <actuator name="katana_motor2_lift_motor"/>
    <joint name="katana_motor2_lift_joint"/>
    <mechanicalReduction>1</mechanicalReduction>
    <motorTorqueConstant>1</motorTorqueConstant>
  </transmission>
  <transmission name="katana_motor3_lift_trans" type="pr2_mechanism_model/SimpleTransmission">
    <actuator name="katana_motor3_lift_motor"/>
    <joint name="katana_motor3_lift_joint"/>
    <mechanicalReduction>1</mechanicalReduction>
    <motorTorqueConstant>1</motorTorqueConstant>
  </transmission>
  <transmission name="katana_motor4_lift_trans" type="pr2_mechanism_model/SimpleTransmission">
    <actuator name="katana_motor4_lift_motor"/>
    <joint name="katana_motor4_lift_joint"/>
    <mechanicalReduction>1</mechanicalReduction>
    <motorTorqueConstant>1</motorTorqueConstant>
  </transmission>
  <transmission name="katana_motor5_wrist_roll_trans" type="pr2_mechanism_model/SimpleTransmission">
    <actuator name="katana_motor5_wrist_roll_motor"/>
    <joint name="katana_motor5_wrist_roll_joint"/>
    <mechanicalReduction>1</mechanicalReduction>
    <motorTorqueConstant>1</motorTorqueConstant>
  </transmission>
  <transmission name="katana_r_finger_trans" type="pr2_mechanism_model/SimpleTransmission">
    <actuator name="katana_r_finger_motor"/>
    <joint name="katana_r_finger_joint"/>
    <mechanicalReduction>1</mechanicalReduction>
    <motorTorqueConstant>1</motorTorqueConstant>
  </transmission>
  <transmission name="katana_l_finger_trans" type="pr2_mechanism_model/SimpleTransmission">
    <actuator name="katana_l_finger_motor"/>
    <joint name="katana_l_finger_joint"/>
    <mechanicalReduction>1</mechanicalReduction>
    <motorTorqueConstant>1</motorTorqueConstant>
  </transmission>
  <gazebo>
    <!-- controller for the 5 arm joints -->
    <plugin filename="libgazebo_ros_controller_manager.so" name="gazebo_ros_controller_manager">
      <alwaysOn>true</alwaysOn>
      <updateRate>1000.0</updateRate>
      <interface:audio name="gazebo_ros_controller_manager_dummy_iface"/>
    </plugin>
    <!-- gripper controller -->
    <plugin filename="libgazebo_ros_katana_gripper.so" name="katana_gripper_controller">
      <alwaysOn>true</alwaysOn>
      <node_namespace>katana</node_namespace>
      <r_finger_joint>katana_r_finger_joint</r_finger_joint>
      <l_finger_joint>katana_l_finger_joint</l_finger_joint>
      <updateRate>1000.0</updateRate>
      <max_torque>0.5</max_torque>
    </plugin>
    <!-- a formal implementation of grasp hack in gazebo with fixed joint -->
    <gripper name="katana_gripper_grasp_hack">
      <grasp_check attach_steps="20" detach_steps="40" min_contact_count="2"/>
      <gripper_link>katana_r_finger_link</gripper_link>
      <gripper_link>katana_l_finger_link</gripper_link>
      <palm_link>katana_gripper_link</palm_link>
    </gripper>
  </gazebo>
  <gazebo reference="katana_base_link">
    <material value="Gazebo/Grey"/>
  </gazebo>
  <gazebo reference="katana_motor1_pan_link">
    <material value="Gazebo/Grey"/>
    <turnGravityOff>true</turnGravityOff>
  </gazebo>
  <gazebo reference="katana_motor2_lift_link">
    <material value="Gazebo/Grey"/>
    <turnGravityOff>true</turnGravityOff>
  </gazebo>
  <gazebo reference="katana_motor3_lift_link">
    <material value="Gazebo/Grey"/>
    <turnGravityOff>true</turnGravityOff>
  </gazebo>
  <gazebo reference="katana_motor4_lift_link">
    <material value="Gazebo/Grey"/>
    <turnGravityOff>true</turnGravityOff>
  </gazebo>
  <gazebo reference="katana_motor5_wrist_roll_link">
    <material value="Gazebo/Grey"/>
    <turnGravityOff>true</turnGravityOff>
  </gazebo>
  <gazebo reference="katana_gripper_link">
    <material value="Gazebo/Grey"/>
    <turnGravityOff>true</turnGravityOff>
  </gazebo>
  <gazebo reference="katana_r_finger_link">
    <material value="Gazebo/Grey"/>
    <turnGravityOff>true</turnGravityOff>
  </gazebo>
  <gazebo reference="katana_l_finger_link">
    <material value="Gazebo/Grey"/>
    <turnGravityOff>true</turnGravityOff>
  </gazebo>
  <gazebo reference="katana_motor1_pan_joint">
    <initial_joint_position>-3.022</initial_joint_position>
  </gazebo>
  <gazebo reference="katana_motor2_lift_joint">
    <initial_joint_position>2.163</initial_joint_position>
  </gazebo>
  <gazebo reference="katana_motor3_lift_joint">
    <initial_joint_position>-2.207</initial_joint_position>
  </gazebo>
  <gazebo reference="katana_motor4_lift_joint">
    <initial_joint_position>-2.026</initial_joint_position>
  </gazebo>
  <gazebo reference="katana_motor5_wrist_roll_joint">
    <initial_joint_position>-2.990</initial_joint_position>
  </gazebo>
  <gazebo reference="katana_r_finger_joint">
    <initial_joint_position>0.3</initial_joint_position>
  </gazebo>
  <gazebo reference="katana_l_finger_joint">
    <initial_joint_position>0.3</initial_joint_position>
  </gazebo>
  <link name="katana_base_link">
    <visual>
      <origin rpy="0 0 0" xyz="0 0 0"/>
      <geometry>
        <mesh filename="package://katana_description/meshes/katana/katana_base_link.stl"/>
      </geometry>
      <material name="grey">
        <color rgba="0.8 0.8 0.8 1"/>
      </material>
    </visual>
    <collision>
      <origin rpy="0 0 0" xyz="0 0 0"/>
      <geometry>
        <mesh filename="package://katana_description/meshes/katana/convex/katana_base_link_convex.stl"/>
      </geometry>
    </collision>
    <inertial>
      <mass value="1.4047990875"/>
      <origin xyz="-0.000327 0.000908 0.058457"/>
      <inertia ixx="0.003000703" ixy="0.000000864" ixz="-0.000011312" iyy="0.002974822" iyz="0.000036294" izz="0.001434739"/>
    </inertial>
  </link>
  <joint name="katana_motor1_pan_joint" type="revolute">
    <!-- Joint 1 in Katana Manual -->
    <parent link="katana_base_link"/>
    <child link="katana_motor1_pan_link"/>
    <origin rpy="0 0 0" xyz="0 0 0.2015"/>
    <axis xyz="0 0 1"/>
    <limit effort="1.5" lower="-3.025528" upper="2.891097" velocity="2.208932"/>
  </joint>
  <link name="katana_motor1_pan_link">
    <visual>
      <origin rpy="0 0 0" xyz="0 0 -0.2015"/>
      <geometry>
        <mesh filename="package://katana_description/meshes/katana/katana_motor1_pan_link.stl"/>
      </geometry>
      <material name="grey"/>
    </visual>
    <collision>
      <origin rpy="0 0 0" xyz="0 0 -0.2015"/>
      <geometry>
        <mesh filename="package://katana_description/meshes/katana/convex/katana_motor1_pan_link_convex.stl"/>
      </geometry>
    </collision>
    <inertial>
      <mass value="0.74793301875"/>
      <origin xyz="-0.000410 -0.001285 -0.016774"/>
      <inertia ixx="0.001737241" ixy="0.000000421" ixz="0.000000650" iyy="0.000998782" iyz="0.000016114" izz="0.001349170"/>
    </inertial>
  </link>
  <joint name="katana_motor2_lift_joint" type="revolute">
    <!-- Joint 2 in Katana Manual -->
    <parent link="katana_motor1_pan_link"/>
    <child link="katana_motor2_lift_link"/>
    <origin rpy="1.57079632679 0 0" xyz="0 0 0"/>
    <axis xyz="0 0 1"/>
    <limit effort="0.6" lower="-0.135228" upper="2.168572" velocity="1.190799"/>
  </joint>
  <link name="katana_motor2_lift_link">
    <visual>
      <origin rpy="-1.57079632679 0 0" xyz="0 0 0"/>
      <geometry>
        <mesh filename="package://katana_description/meshes/katana/katana_motor2_lift_link.stl"/>
      </geometry>
      <!-- <geometry>
          <cylinder length="${link2_length}" radius="0.02"/>
        </geometry>
        <origin rpy="0 ${-M_PI/2} 0" xyz="${link2_length/2} 0 0" /> -->
      <material name="grey"/>
    </visual>
    <collision>
      <origin rpy="-1.57079632679 0 0" xyz="0 0 0"/>
      <geometry>
        <mesh filename="package://katana_description/meshes/katana/convex/katana_motor2_lift_link_convex.stl"/>
      </geometry>
    </collision>
    <inertial>
      <mass value="0.80174941875"/>
      <origin xyz="0.092420 0.005283 0.000172"/>
      <inertia ixx="0.000478252" ixy="0.000081166" ixz="0.000003961" iyy="0.004314636" iyz="0.000000332" izz="0.004625444"/>
    </inertial>
  </link>
  <joint name="katana_motor3_lift_joint" type="revolute">
    <!-- Joint 3 in Katana Manual -->
    <parent link="katana_motor2_lift_link"/>
    <child link="katana_motor3_lift_link"/>
    <origin rpy="0 0 0" xyz="0.19 0 0"/>
    <axis xyz="0 0 1"/>
    <!-- unexplicably, the measured velocity limit of this motor is exactly half of what vel_enc2rad(180) says -->
    <limit effort="0.25" lower="-2.221804" upper="2.054223" velocity="1.190799"/>
  </joint>
  <link name="katana_motor3_lift_link">
    <visual>
      <origin rpy="-1.57079632679 0 0" xyz="0 0 0"/>
      <geometry>
        <mesh filename="package://katana_description/meshes/katana/katana_motor3_lift_link.stl"/>
      </geometry>
      <!--<geometry>
          <cylinder length="${link3_length}" radius="0.02"/>
        </geometry>
        <origin rpy="0 ${-M_PI/2} 0" xyz="${link3_length/2} 0 0" />-->
      <material name="grey"/>
    </visual>
    <collision>
      <origin rpy="-1.57079632679 0 0" xyz="0 0 0"/>
      <geometry>
        <mesh filename="package://katana_description/meshes/katana/convex/katana_motor3_lift_link_convex.stl"/>
      </geometry>
    </collision>
    <inertial>
      <mass value="0.79241664375"/>
      <origin xyz="0.058036 0.008963 -0.000187"/>
      <inertia ixx="0.001156089" ixy="0.000112877" ixz="-0.000004398" iyy="0.002305646" iyz="-0.000000036" izz="0.003128648"/>
    </inertial>
  </link>
  <joint name="katana_motor4_lift_joint" type="revolute">
    <!-- Joint 4 in Katana Manual -->
    <parent link="katana_motor3_lift_link"/>
    <child link="katana_motor4_lift_link"/>
    <origin rpy="3.14159265359 0 0" xyz="0.139 0 0"/>
    <axis xyz="0 0 1"/>
    <limit effort="0.1" lower="-2.033309" upper="1.876133" velocity="2.208932"/>
  </joint>
  <link name="katana_motor4_lift_link">
    <visual>
      <origin rpy="1.57079632679 0 0" xyz="0 0 0"/>
      <geometry>
        <mesh filename="package://katana_description/meshes/katana/katana_motor4_lift_link.stl"/>
      </geometry>
      <!-- <geometry>
          <cylinder length="${link4_length}" radius="0.02"/>
        </geometry>
        <origin rpy="0 ${-M_PI/2} 0" xyz="${link4_length/2} 0 0" /> -->
      <material name="grey"/>
    </visual>
    <collision>
      <origin rpy="1.57079632679 0 0" xyz="0 0 0"/>
      <geometry>
        <mesh filename="package://katana_description/meshes/katana/convex/katana_motor4_lift_link_convex.stl"/>
      </geometry>
    </collision>
    <inertial>
      <mass value="0.69149323125"/>
      <origin xyz="0.050401 0.005807 0.000000"/>
      <inertia ixx="0.000765999" ixy="0.000045260" ixz="-0.000001210" iyy="0.001504115" iyz="0.000000147" izz="0.001887277"/>
    </inertial>
  </link>
  <joint name="katana_motor5_wrist_roll_joint" type="revolute">
    <!-- Joint 5 in Katana Manual -->
    <parent link="katana_motor4_lift_link"/>
    <child link="katana_motor5_wrist_roll_link"/>
    <origin rpy="1.57079632679 0 -1.57079632679" xyz="0.1523 0 0"/>
    <axis xyz="0 0 1"/>
    <limit effort="0.01" lower="-2.993240" upper="2.870985" velocity="2.208932"/>
  </joint>
  <link name="katana_motor5_wrist_roll_link">
    <visual>
      <origin rpy="0 3.14159265359 0" xyz="0 0 0"/>
      <geometry>
        <mesh filename="package://katana_description/meshes/katana/katana_motor5_wrist_roll_link.stl"/>
      </geometry>
      <!--<geometry>
          <cylinder length="${link5_length}" radius="0.02"/>
        </geometry>
        <origin rpy="0 ${-M_PI/2} 0" xyz="${link5_length/2} 0 0" />-->
      <material name="grey"/>
    </visual>
    <collision>
      <origin rpy="0 3.14159265359 0" xyz="0 0 0"/>
      <geometry>
        <mesh filename="package://katana_description/meshes/katana/convex/katana_motor5_wrist_roll_link_convex.stl"/>
      </geometry>
    </collision>
    <inertial>
      <mass value="0.25622555625"/>
      <origin xyz="-0.003140899 0.000013920 0.001680144"/>
      <inertia ixx="0.000120481" ixy="0.000000015" ixz="-0.000001089" iyy="0.000132130" iyz="-0.000000124" izz="0.000093522"/>
    </inertial>
  </link>
  <joint name="katana_gripper_joint" type="fixed">
    <parent link="katana_motor5_wrist_roll_link"/>
    <child link="katana_gripper_link"/>
    <origin rpy="0 1.57079632679 0" xyz="0 0 -0.0323"/>
  </joint>
  <link name="katana_gripper_link">
    <visual>
      <origin rpy="0 3.14159265359 0" xyz="0 0 0"/>
      <geometry>
        <mesh filename="package://katana_description/meshes/katana/katana_gripper_link.stl"/>
      </geometry>
      <material name="grey"/>
    </visual>
    <collision>
      <origin rpy="0 3.14159265359 0" xyz="0 0 0"/>
      <geometry>
        <mesh filename="package://katana_description/meshes/katana/convex/katana_gripper_link_convex.stl"/>
      </geometry>
    </collision>
    <inertial>
      <mass value="0.0552136183596"/>
      <origin xyz="-0.014379 -0.000000 0.000006"/>
      <inertia ixx="0.000011468" ixy="0.000000000" ixz="0.000000007" iyy="0.000013830" iyz="0.000000000" izz="0.000011290"/>
    </inertial>
  </link>
  <joint name="katana_r_finger_joint" type="revolute">
    <parent link="katana_gripper_link"/>
    <child link="katana_r_finger_link"/>
    <origin rpy="0 0 0" xyz="0.034 0 0"/>
    <axis xyz="0 0 1"/>
    <limit effort="0.5" lower="-0.44" upper="0.30" velocity="0.718834"/>
  </joint>
  <link name="katana_r_finger_link">
    <visual>
      <origin rpy="0 3.14159265359 0" xyz="0 0 0"/>
      <geometry>
        <mesh filename="package://katana_description/meshes/katana/katana_gripper_r_finger.stl"/>
      </geometry>
      <material name="grey"/>
    </visual>
    <collision>
      <origin rpy="0 3.14159265359 0" xyz="0 0 0"/>
      <geometry>
        <mesh filename="package://katana_description/meshes/katana/convex/katana_gripper_r_finger_convex.stl"/>
      </geometry>
    </collision>
    <inertial>
      <mass value="0.0251722230462"/>
      <origin xyz="0.001784 0.025167 -.001603"/>
      <inertia ixx="0.000005990" ixy="0.000008473" ixz="0.000001448" iyy="0.000019757" iyz="-0.000000996" izz="0.000023588"/>
    </inertial>
  </link>
  <joint name="katana_l_finger_joint" type="revolute">
    <parent link="katana_gripper_link"/>
    <child link="katana_l_finger_link"/>
    <origin rpy="3.14159265359 0 0" xyz="0.034 0 0"/>
    <axis xyz="0 0 1"/>
    <limit effort="0.5" lower="-0.44" upper="0.30" velocity="0.718834"/>
  </joint>
  <link name="katana_l_finger_link">
    <visual>
      <origin rpy="0 3.14159265359 0" xyz="0 0 0"/>
      <geometry>
        <mesh filename="package://katana_description/meshes/katana/katana_gripper_l_finger.stl"/>
      </geometry>
      <material name="grey"/>
    </visual>
    <collision>
      <origin rpy="0 3.14159265359 0" xyz="0 0 0"/>
      <geometry>
        <mesh filename="package://katana_description/meshes/katana/convex/katana_gripper_l_finger_convex.stl"/>
      </geometry>
    </collision>
    <inertial>
      <mass value="0.0251722230462"/>
      <origin xyz="0.001784 0.025167 -.001603"/>
      <inertia ixx="0.000005990" ixy="0.000008473" ixz="0.000001448" iyy="0.000019757" iyz="-0.000000996" izz="0.000023588"/>
    </inertial>
  </link>
  <joint name="katana_gripper_tool_frame_joint" type="fixed">
    <parent link="katana_motor5_wrist_roll_link"/>
    <child link="katana_gripper_tool_frame"/>
    <origin rpy="0 1.57079632679 0" xyz="0 0 -0.11"/>
  </joint>
  <link name="katana_gripper_tool_frame">
    <!-- This is the coordinate system of the tool (this is the position
         used in IK etc., relative to the base frame); there is no actual
         arm part attached to this link -->
  </link>
  <joint name="kurtana_baseplate_katana_baseplate_joint" type="fixed">
    <parent link="katana_baseplate_link"/>
    <child link="katana_base_link"/>
    <origin rpy="0 0 0" xyz="0 0 0"/>
  </joint>
  <joint name="top_base_joint" type="fixed">
    <parent link="top_plate"/>
    <child link="kurtana_baseplate_link"/>
    <origin xyz="0 0.0 0.2115"/>
  </joint>
</robot>

